File: Data.csv
DensityX,Composition,Time s,Temperature °C,Shear Rate 1/s,Shear Stress Pa,Instantaneous Viscosity Pas,Strain
4.506,10,1.004,25,9.665,661.1,68.4,19.27
4.506,10,7.008,25,69,1409,20.43,315.6
4.506,10,13.01,25,128.8,1397,10.84,972.2
4.506,10,19.01,25.1,187.9,1293,6.883,1992
4.506,10,25.01,25,248.3,1158,4.665,3368
4.506,10,31.01,25,308.4,1104,3.58,5109
4.506,10,37.01,25,367.7,921.4,2.506,7204
4.506,10,43.01,25,427.6,993.5,2.323,9663
4.506,10,49.01,25,487,1028,2.111,1.25E+04
4.506,10,55.01,25,547.1,1105,2.019,1.57E+04
4.506,10,61.01,25,606.6,1258,2.074,1.92E+04
4.506,10,67.01,25,666.5,1170,1.755,2.31E+04
4.506,10,73.01,25,725.8,1006,1.385,2.74E+04
4.506,10,79.01,25,785.8,1122,1.428,3.20E+04
4.506,10,85.01,25,845.3,979.3,1.159,3.69E+04
4.506,10,91.01,25,905.5,1204,1.329,4.23E+04
4.506,10,97.01,25,964.7,1151,1.193,4.80E+04
4.506,10,103.1,25,966.4,1099,1.137,5.39E+04
4.506,10,109.1,25,906.9,903.2,0.9959,5.95E+04
4.506,10,115.1,25,846.8,869.6,1.027,6.47E+04
4.506,10,121.1,25,787,829.1,1.054,6.96E+04
4.506,10,127.1,25,727.3,897.5,1.234,7.41E+04
4.506,10,133.1,25,667.5,1119,1.676,7.83E+04
4.506,10,139.1,25,608,984.7,1.62,8.20E+04
4.506,10,145.1,25,548.3,1045,1.905,8.55E+04
4.506,10,151.1,25,488.7,1056,2.161,8.85E+04
4.506,10,157.1,25,428.7,1044,2.436,9.12E+04
4.506,10,163.1,25,368.7,912.3,2.475,9.36E+04
4.506,10,169.1,25,309.1,828.7,2.681,9.55E+04
4.506,10,175.1,25,249.2,1078,4.326,9.72E+04
4.506,10,181.1,25,189.8,884.3,4.658,9.84E+04
4.506,10,187.1,25,130.1,917.9,7.055,9.93E+04
4.506,10,193.1,25,70.37,740.9,10.53,9.99E+04
4.506,10,199.1,25,10.5,712.2,67.84,1.00E+05
4.506,10,5.008,25,49.06,211,4.302,177
4.506,10,11.01,25,109,182.5,1.674,714.8
4.506,10,17.01,25,168.5,156.7,0.9301,1613
4.506,10,23.01,25,228.4,176.5,0.7729,2869
4.506,10,29.01,25,287.9,182.6,0.6343,4488
4.506,10,35.01,25,347.8,125.2,0.3598,6467
4.506,10,41.01,25,407.3,117.6,0.2888,8801
4.506,10,47.01,25,467.3,111.7,0.2391,1.15E+04
4.506,10,53.01,25,526.7,109.2,0.2074,1.46E+04
4.506,10,59.01,25,586.6,106.7,0.1819,1.80E+04
4.506,10,65.03,25,646.6,106.4,0.1646,2.18E+04
4.506,10,71.03,25,706,106.4,0.1506,2.59E+04
4.506,10,77.01,25,766.1,107.5,0.1404,3.04E+04
4.506,10,83.03,25,825.5,106.7,0.1293,3.52E+04
4.506,10,89.03,25,885.5,107.8,0.1217,4.05E+04
4.506,10,95.03,25,944.9,106.7,0.1129,4.60E+04
4.506,10,101.1,25,986.2,104.3,0.1057,5.20E+04
4.506,10,107.1,25,926.7,101.8,0.1099,5.77E+04
4.506,10,113.1,25,866.7,99.28,0.1145,6.31E+04
4.506,10,119.1,25,806.8,95.66,0.1186,6.81E+04
4.506,10,125.1,25,747.3,94.01,0.1258,7.27E+04
4.506,10,131.1,25,687.4,90.8,0.1321,7.69E+04
4.506,10,137.1,25,627.9,87.53,0.1394,8.09E+04
4.506,10,143.1,25,568,85.21,0.15,8.44E+04
4.506,10,149.1,25,508.5,81.84,0.1609,8.76E+04
4.506,10,155.1,25,448.5,78.41,0.1748,9.04E+04
4.506,10,161.1,25,389.1,76.22,0.1959,9.29E+04
4.506,10,167.1,25,329.1,72.69,0.2209,9.50E+04
4.506,10,173.1,25,269.7,64.97,0.2409,9.67E+04
4.506,10,179.1,25,209.7,57.53,0.2743,9.81E+04
4.506,10,185.1,25,150.2,47.49,0.3161,9.91E+04
4.506,10,191.1,25,90.29,35.26,0.3905,9.98E+04
4.506,10,197.1,25,30.33,20.78,0.6853,1.00E+05
4.506,20,3.007,25,29.25,42.89,1.466,77.73
4.506,20,9.008,25,88.58,75.92,0.8571,494.9
4.506,20,15.01,25,148.7,59.57,0.4006,1273
4.506,20,21.01,25,208.6,42.97,0.206,2411
4.506,20,27.01,25,268.1,41.8,0.1559,3911
4.506,20,33.01,25,328,44.65,0.1361,5765
4.506,20,39.01,25,387.5,42.52,0.1097,7985
4.506,20,45.01,25,447.4,43.5,0.09723,1.06E+04
4.506,20,51.01,25,506.9,42.91,0.08465,1.35E+04
4.506,20,57.01,25,566.9,42.34,0.07468,1.68E+04
4.506,20,63.01,25,626.3,42.65,0.0681,2.05E+04
4.506,20,69.01,25,686.3,43.94,0.06403,2.45E+04
4.506,20,75.01,25,745.7,42.9,0.05753,2.88E+04
4.506,20,81.01,25,805.8,42.9,0.05324,3.36E+04
4.506,20,87.01,25,865.2,42.9,0.04958,3.87E+04
4.506,20,93.01,25,925.1,42.82,0.04629,4.41E+04
4.506,20,99.01,25,985.1,42.66,0.04331,5.00E+04
4.506,20,105.1,25,946.5,39.89,0.04214,5.58E+04
4.506,20,111.1,25,886.5,39.38,0.04442,6.13E+04
4.506,20,117.1,25,827,38.16,0.04614,6.64E+04
4.506,20,123.1,25,767.1,37.66,0.04909,7.11E+04
4.506,20,129.1,25,707.6,36.57,0.05168,7.55E+04
4.506,20,135.1,25,647.6,37.21,0.05746,7.95E+04
4.506,20,141.1,25,588.2,34.95,0.05942,8.32E+04
4.506,20,147.1,25,528.2,33.77,0.06392,8.65E+04
4.506,20,153.1,25,468.8,33.38,0.07121,8.95E+04
4.506,20,159.1,25,408.8,31.92,0.07808,9.20E+04
4.506,20,165.1,25,349.4,31.41,0.08992,9.43E+04
4.506,20,171.1,25,289.4,21.31,0.07364,9.61E+04
4.506,20,177.1,25,229.4,19.46,0.08479,9.76E+04
4.506,20,183.1,25,170,17.46,0.1027,9.88E+04
4.506,20,189.1,25,110,15.44,0.1404,9.96E+04
4.506,20,195.1,25,50.58,11.71,0.2316,1.00E+05
4.506,20,1.01,25,9.516,160.8,16.9,19.36
4.506,20,7.012,25,68.89,115.6,1.678,316.7
4.506,20,13.01,25,128.8,164.2,1.275,974.9
4.506,20,19.01,25,188.3,43.83,0.2328,1991
4.506,20,25.01,25,248.3,46.39,0.1868,3370
4.506,20,31.01,25,308.3,99.45,0.3226,5109
4.506,20,37.01,25,367.6,105.9,0.288,7203
4.506,20,43.01,25,427.7,86.5,0.2023,9663
4.506,20,49.01,25,487.1,69.31,0.1423,1.25E+04
4.506,20,55.01,25,547,66.25,0.1211,1.57E+04
4.506,20,61.01,25,606.5,65.75,0.1084,1.92E+04
4.506,20,67.01,25,666.4,61.64,0.0925,2.31E+04
4.506,20,73.01,25,725.9,63.48,0.08746,2.74E+04
4.506,20,79.01,25,785.8,57.65,0.07336,3.20E+04
4.506,20,85.01,25,845.4,53.49,0.06328,3.69E+04
4.506,20,91.01,25,905.3,49.79,0.05499,4.23E+04
4.506,20,97.01,25,964.8,58.06,0.06018,4.80E+04
4.506,20,103.1,25,966.3,61.91,0.06407,5.39E+04
4.506,20,109.1,25,906.8,58.42,0.06442,5.95E+04
4.506,20,115.1,25,846.8,46.16,0.05451,6.47E+04
4.506,20,121.1,25,787.4,43.87,0.05572,6.96E+04
4.506,20,127.1,25,727.4,44.54,0.06123,7.41E+04
4.506,20,133.1,25,667.5,47.29,0.07085,7.82E+04
4.506,20,139.1,25,608,47.39,0.07794,8.20E+04
4.506,20,145.1,25,548,45.62,0.08325,8.55E+04
4.506,20,151.1,25,488.6,39.82,0.0815,8.85E+04
4.506,20,157.1,25,428.6,40.75,0.09507,9.12E+04
4.506,20,163.1,25,369.2,38.81,0.1051,9.36E+04
4.506,20,169.1,25,309.2,40.79,0.1319,9.55E+04
4.506,20,175.1,25,249.3,32.83,0.1317,9.72E+04
4.506,20,181.1,25,189.8,29.33,0.1545,9.84E+04
4.506,20,187.1,25,129.8,30.3,0.2334,9.93E+04
4.506,20,193.1,25,70.38,23.12,0.3285,9.99E+04
4.506,20,199.1,25,10.42,5.868,0.563,1.00E+05
4.506,30,5.007,25,49.07,56.49,1.151,178
4.506,30,11.01,25,109,73.5,0.6742,714.8
4.506,30,17.01,25,168.5,58.04,0.3445,1613
4.506,30,23.01,25,228.4,54.95,0.2405,2869
4.506,30,29.01,25,287.9,44.44,0.1543,4488
4.506,30,35.01,25,347.9,46.67,0.1342,6467
4.506,30,41.01,25,407.3,46.82,0.115,8801
4.506,30,47.01,25,467.3,45.66,0.09772,1.15E+04
4.506,30,53.01,25,526.7,43.77,0.0831,1.46E+04
4.506,30,59.01,25,586.6,43.69,0.07447,1.80E+04
4.506,30,65.01,25,646.6,43.57,0.06738,2.18E+04
4.506,30,71.01,25,706.1,43.78,0.062,2.59E+04
4.506,30,77.01,25,766,44.55,0.05816,3.04E+04
4.506,30,83.01,25,825.5,44.62,0.05405,3.52E+04
4.506,30,89.01,25,885.4,45.25,0.05111,4.05E+04
4.506,30,95.01,25,945,46.21,0.04891,4.60E+04
4.506,30,101,25,986.1,43.48,0.04409,5.20E+04
4.506,30,107.1,25,926.7,41.04,0.04429,5.77E+04
4.506,30,113.1,25,866.6,41.23,0.04758,6.30E+04
4.506,30,119.1,25,807.2,40.06,0.04963,6.80E+04
4.506,30,125.1,25,747.2,38.94,0.05211,7.26E+04
4.506,30,131.1,25,687.7,38.11,0.05542,7.69E+04
4.506,30,137.1,25,627.8,37.86,0.0603,8.08E+04
4.506,30,143.1,25,568.4,37.02,0.06514,8.43E+04
4.506,30,149.1,25,508.4,36.37,0.07154,8.75E+04
4.506,30,155.1,25,448.9,35.25,0.07853,9.04E+04
4.506,30,161.1,25,389,34.84,0.08956,9.28E+04
4.506,30,167.1,25,329.1,38.1,0.1158,9.49E+04
4.506,30,173.1,25,269.6,25.42,0.09429,9.67E+04
4.506,30,179.1,25,209.6,22.6,0.1078,9.81E+04
4.506,30,185.1,25,150.2,20.02,0.1334,9.91E+04
4.506,30,191.1,25,90.2,16.33,0.181,9.97E+04
4.506,30,197.1,25,30.25,13.29,0.4394,1.00E+05
4.506,30,3.027,25,29.83,853.1,28.6,79.91
4.506,30,9.028,25,89.25,1143,12.81,500.4
4.506,30,15.03,25,149,554.9,3.723,1278
4.506,30,21.03,25,208.6,436.5,2.093,2419
4.506,30,27.03,25,268.6,497.3,1.851,3920
4.506,30,33.03,25,328,417.8,1.274,5777
4.506,30,39.03,25,388.1,465,1.198,7999
4.506,30,45.03,25,447.5,490.4,1.096,1.06E+04
4.506,30,51.03,25,507.4,474.2,0.9346,1.35E+04
4.506,30,57.03,25,566.9,420.3,0.7414,1.68E+04
4.506,30,63.03,25,626.7,439.5,0.7013,2.05E+04
4.506,30,69.03,25,686.7,412.6,0.6008,2.45E+04
4.506,30,75.03,25,746.2,382.8,0.513,2.89E+04
4.506,30,81.03,25,805.9,643.1,0.798,3.36E+04
4.506,30,87.03,25,865.6,885.6,1.023,3.87E+04
4.506,30,93.03,25,925.4,909.2,0.9825,4.42E+04
4.506,30,99.03,25,985.1,669,0.6791,5.00E+04
4.506,30,105.1,25,946.5,560.7,0.5923,5.58E+04
4.506,30,111.1,25,886.5,538.3,0.6072,6.13E+04
4.506,30,117.1,25,827.1,592.9,0.7168,6.64E+04
4.506,30,123.1,25,767.2,686,0.8942,7.12E+04
4.506,30,129.1,25,707.1,536.4,0.7586,7.55E+04
4.506,30,135.1,25,647.7,538,0.8307,7.96E+04
4.506,30,141.1,25,587.7,572.1,0.9734,8.32E+04
4.506,30,147.1,25,528.3,666.5,1.262,8.65E+04
4.506,30,153.1,25,468.3,573.4,1.224,8.95E+04
4.506,30,159.1,25,408.9,574.8,1.406,9.21E+04
4.506,30,165.1,25,348.9,584.4,1.675,9.43E+04
4.506,30,171.1,25,289.4,556,1.921,9.61E+04
4.506,30,177.1,25,229.5,545.9,2.378,9.76E+04
4.506,30,183.1,25,170,522.2,3.071,9.88E+04
4.506,30,189.1,25,110.1,508,4.614,9.96E+04
4.506,30,195.1,25,50.63,468.2,9.248,1.00E+05
4.506,30,1.006,25,9.642,474.9,49.25,19.56
4.506,30,7.009,25,68.92,440.6,6.393,316.6
4.506,30,13.01,25,129,643,4.986,972.7
4.506,30,19.01,25,188.1,495,2.631,1992
4.506,30,25.01,25,248.3,635.9,2.561,3369
4.506,30,31.01,25,308.3,804.4,2.61,5109
4.506,30,37.01,25,367.6,614.8,1.673,7199
4.506,30,43.01,25,427.7,503.4,1.177,9663
4.506,30,49.01,25,487,377.4,0.7749,1.25E+04
4.506,30,55.01,25,547,353.2,0.6456,1.57E+04
4.506,30,61.01,25,606.6,401.7,0.6621,1.92E+04
4.506,30,67.01,25,666.4,336.5,0.5049,2.31E+04
4.506,30,73.01,25,725.9,356.7,0.4913,2.74E+04
4.506,30,79.01,25,785.9,323.9,0.4121,3.20E+04
4.506,30,85.01,25,845.3,293.5,0.3473,3.69E+04
4.506,30,91.01,25,905.4,282,0.3114,4.23E+04
4.506,30,97.01,25,964.8,294.3,0.305,4.80E+04
4.506,30,103.1,25,966.3,284.7,0.2946,5.40E+04
4.506,30,109.1,25,906.9,320.7,0.3536,5.95E+04
4.506,30,115.1,25,846.9,364.3,0.4302,6.48E+04
4.506,30,121.1,25,787.5,344.5,0.4375,6.96E+04
4.506,30,127.1,25,727.4,339.5,0.4667,7.41E+04
4.506,30,133.1,25,667.4,302,0.4525,7.83E+04
4.506,30,139.1,25,608,305.8,0.5029,8.21E+04
4.506,30,145.1,25,548.1,326.3,0.5954,8.55E+04
4.506,30,151.1,25,488.7,340.3,0.6963,8.85E+04
4.506,30,157.1,25,428.7,337.2,0.7865,9.13E+04
4.506,30,163.1,25,368.8,413.6,1.121,9.36E+04
4.506,30,169.1,25,309.1,433.3,1.402,9.56E+04
4.506,30,175.1,25,249.3,470.6,1.887,9.72E+04
4.506,30,181.1,25,189.7,465.2,2.452,9.85E+04
4.506,30,187.1,25,130,489,3.76,9.94E+04
4.506,30,193.1,25,70.43,524.1,7.442,9.99E+04
4.506,30,199.1,25,10.48,287.8,27.46,1.00E+05
1.74,10,5.008,25,48.98,1457,29.75,176.9
1.74,10,11.01,25,108.7,1383,12.72,713.1
1.74,10,17.01,25,168.6,815.2,4.834,1613
1.74,10,23.01,25,228.4,654.6,2.866,2869
1.74,10,29.01,25,287.9,451.8,1.569,4488
1.74,10,35.01,25,347.8,377.5,1.085,6467
1.74,10,41.01,25,407.3,282.6,0.6938,8801
1.74,10,47.01,25,467.3,225.3,0.4821,1.15E+04
1.74,10,53.01,25,526.7,181.6,0.3447,1.46E+04
1.74,10,59.01,25,586.7,174.9,0.2981,1.80E+04
1.74,10,65.01,25,646.6,172,0.266,2.18E+04
1.74,10,71.01,25,706.1,169.3,0.2397,2.59E+04
1.74,10,77.01,25,766,164.4,0.2147,3.04E+04
1.74,10,83.01,25,825.5,158.9,0.1925,3.52E+04
1.74,10,89.01,25,885.5,155.4,0.1755,4.05E+04
1.74,10,95.01,25,944.9,153.7,0.1626,4.60E+04
1.74,10,101,25,986.1,148.5,0.1506,5.20E+04
1.74,10,107.1,25,926.7,142.6,0.1538,5.77E+04
1.74,10,113.1,25,866.7,138.4,0.1596,6.30E+04
1.74,10,119.1,25,807.2,135.3,0.1677,6.80E+04
1.74,10,125.1,25,747.2,131.5,0.176,7.26E+04
1.74,10,131.1,25,687.8,128,0.1862,7.69E+04
1.74,10,137.1,25,627.8,124.5,0.1983,8.08E+04
1.74,10,143.1,25,568.4,120.1,0.2112,8.43E+04
1.74,10,149.1,25,508.4,117.2,0.2306,8.75E+04
1.74,10,155.1,25,448.9,112.6,0.2507,9.04E+04
1.74,10,161.1,25,389,109.9,0.2826,9.28E+04
1.74,10,167.1,25,329,105.4,0.3203,9.49E+04
1.74,10,173.1,25,269.6,96.4,0.3576,9.67E+04
1.74,10,179.1,25,209.6,85.14,0.4062,9.80E+04
1.74,10,185.1,25,150.1,69.83,0.4651,9.91E+04
1.74,10,191.1,25,90.2,48.73,0.5403,9.97E+04
1.74,10,197.1,25,30.74,32.98,1.073,1.00E+05
1.74,10,3.007,25,29.26,603.7,20.63,77.73
1.74,10,9.007,25,88.72,556.9,6.277,494.9
1.74,10,15.01,25,148.7,570.4,3.837,1270
1.74,10,21.01,25,208.6,501,2.401,2411
1.74,10,27.01,25,268.1,406.2,1.515,3911
1.74,10,33.01,25,328,338.4,1.031,5765
1.74,10,39.01,25,387.5,305.4,0.7882,7985
1.74,10,45.03,25,447.5,273.2,0.6105,1.06E+04
1.74,10,51.03,25,507.4,251,0.4946,1.35E+04
1.74,10,57.01,25,566.9,235.4,0.4153,1.68E+04
1.74,10,63.03,25,626.8,224.3,0.3578,2.05E+04
1.74,10,69.03,25,686.7,214.6,0.3124,2.45E+04
1.74,10,75.03,25,746.2,214,0.2868,2.89E+04
1.74,10,81.03,25,806.2,215.9,0.2678,3.36E+04
1.74,10,87.03,25,865.6,211.2,0.244,3.87E+04
1.74,10,93.03,25,925.6,206.6,0.2232,4.42E+04
1.74,10,99.03,25,985.1,197.2,0.2002,5.00E+04
1.74,10,105.1,25,946.5,196.5,0.2077,5.59E+04
1.74,10,111.1,25,886.5,189.6,0.2139,6.13E+04
1.74,10,117.1,25,827.1,184.7,0.2234,6.64E+04
1.74,10,123.1,25,767.1,180.3,0.2351,7.12E+04
1.74,10,129.1,25,707.6,175.6,0.2481,7.56E+04
1.74,10,135.1,25,647.7,171.3,0.2645,7.96E+04
1.74,10,141.1,25,587.8,167.7,0.2853,8.33E+04
1.74,10,147.1,25,528.3,163.2,0.309,8.66E+04
1.74,10,153.1,25,468.3,159.4,0.3404,8.95E+04
1.74,10,159.1,25,408.8,155.9,0.3812,9.21E+04
1.74,10,165.1,25,348.9,149.2,0.4276,9.43E+04
1.74,10,171.1,25,289.4,139.6,0.4824,9.62E+04
1.74,10,177.1,25,229.5,125.9,0.5484,9.77E+04
1.74,10,183.1,25,170,109.5,0.644,9.88E+04
1.74,10,189.1,25,110.1,79.72,0.7242,9.96E+04
1.74,10,195.1,25,50.62,66.62,1.316,1.00E+05
1.74,10,1.004,25,9.517,197.8,20.79,19.05
1.74,10,7.008,25,68.89,183.7,2.666,315.3
1.74,10,13.01,25,128.8,159.8,1.24,974.9
1.74,10,19.01,25,188.3,145.1,0.7707,1991
1.74,10,25.01,25,248.3,151.7,0.611,3370
1.74,10,31.01,25,308.2,150.3,0.4878,5109
1.74,10,37.01,25,367.6,141.3,0.3844,7203
1.74,10,43.01,25,427.6,130.6,0.3055,9663
1.74,10,49.03,25,487.1,122.3,0.2511,1.25E+04
1.74,10,55.01,25,547.1,117.4,0.2146,1.57E+04
1.74,10,61.03,25,606.5,114.8,0.1893,1.92E+04
1.74,10,67.03,25,666.4,110.2,0.1653,2.31E+04
1.74,10,73.03,25,725.9,109.5,0.1508,2.74E+04
1.74,10,79.03,25,785.9,107.7,0.1371,3.20E+04
1.74,10,85.03,25,845.3,103.1,0.122,3.69E+04
1.74,10,91.03,25,905.3,105.6,0.1167,4.23E+04
1.74,10,97.03,25,964.8,104.9,0.1088,4.80E+04
1.74,10,103.1,25,966.3,100.6,0.1041,5.39E+04
1.74,10,109.1,25,906.8,97.11,0.1071,5.95E+04
1.74,10,115.1,25,846.9,94.53,0.1116,6.47E+04
1.74,10,121.1,25,787.4,91.39,0.1161,6.96E+04
1.74,10,127.1,25,727.4,90.05,0.1238,7.41E+04
1.74,10,133.1,25,667.5,87.99,0.1318,7.82E+04
1.74,10,139.1,25,608,86.37,0.1421,8.20E+04
1.74,10,145.1,25,548.1,83.57,0.1525,8.55E+04
1.74,10,151.1,25,488.6,81.48,0.1667,8.85E+04
1.74,10,157.1,25,428.7,79.25,0.1849,9.12E+04
1.74,10,163.1,25,368.7,76.61,0.2078,9.36E+04
1.74,10,169.1,25,309.2,72.1,0.2332,9.55E+04
1.74,10,175.1,25,249.3,66.43,0.2665,9.72E+04
1.74,10,181.1,25,189.9,61.76,0.3253,9.84E+04
1.74,10,187.1,25,129.9,51.96,0.4,9.93E+04
1.74,10,193.1,25,70.42,35.25,0.5005,9.99E+04
1.74,10,199.1,25,10.46,13.82,1.32,1.00E+05
1.74,20,5.013,25,49.07,90.94,1.853,178
1.74,20,11.01,25,108.5,77.87,0.7175,712.8
1.74,20,17.01,25,168.5,61.64,0.3659,1610
1.74,20,23.01,25,228.4,54.47,0.2384,2869
1.74,20,29.01,25,287.9,40.08,0.1392,4488
1.74,20,35.01,25,347.9,40.91,0.1176,6467
1.74,20,41.01,25,407.3,39.4,0.09673,8801
1.74,20,47.01,25,467.3,37.25,0.07972,1.15E+04
1.74,20,53.01,25,526.8,35.36,0.06712,1.46E+04
1.74,20,59.01,25,586.7,36.41,0.06206,1.80E+04
1.74,20,65.01,25,646.6,36.51,0.05646,2.18E+04
1.74,20,71.01,25,706.1,36.49,0.05168,2.59E+04
1.74,20,77.01,25,766.1,36.16,0.04719,3.04E+04
1.74,20,83.01,25,825.5,36.63,0.04437,3.52E+04
1.74,20,89.01,25,885.5,36.58,0.04131,4.05E+04
1.74,20,95.01,25,944.9,35.97,0.03807,4.60E+04
1.74,20,101.1,25,985.7,34.63,0.03513,5.20E+04
1.74,20,107.1,25,926.2,33.89,0.03659,5.77E+04
1.74,20,113.1,25,866.3,33.17,0.03828,6.31E+04
1.74,20,119.1,25,806.8,32.4,0.04016,6.81E+04
1.74,20,125.1,25,746.8,32.19,0.04311,7.27E+04
1.74,20,131.1,25,687.4,31.67,0.04607,7.69E+04
1.74,20,137.1,25,627.3,31.43,0.0501,8.08E+04
1.74,20,143.1,25,567.9,31.04,0.05465,8.44E+04
1.74,20,149.1,25,508,29.29,0.05767,8.75E+04
1.74,20,155.1,25,448.5,28.24,0.06297,9.04E+04
1.74,20,161.1,25,388.6,23.9,0.06149,9.28E+04
1.74,20,167.1,25,328.6,25.79,0.07849,9.49E+04
1.74,20,173.1,25,269.2,16.28,0.06047,9.67E+04
1.74,20,179.1,25,209.2,15.58,0.07446,9.81E+04
1.74,20,185.1,25,149.7,14.99,0.1001,9.91E+04
1.74,20,191.1,25,89.78,13.26,0.1477,9.97E+04
1.74,20,197.1,25,30.32,9.206,0.3036,1.00E+05
1.74,20,3.008,25,29.25,111.5,3.812,77.72
1.74,20,9.007,25,88.73,91.55,1.032,494.9
1.74,20,15.01,25,148.7,66.91,0.4501,1273
1.74,20,21.01,25,208.6,52.48,0.2516,2411
1.74,20,27.01,25,268.1,40.96,0.1528,3911
1.74,20,33.01,25,328,37.46,0.1142,5765
1.74,20,39.01,25,387.5,34.48,0.08897,7985
1.74,20,45.01,25,447.5,31.02,0.06933,1.06E+04
1.74,20,51.01,25,506.9,30.44,0.06004,1.35E+04
1.74,20,57.01,25,566.9,30.73,0.0542,1.68E+04
1.74,20,63.01,25,626.3,31.08,0.04962,2.05E+04
1.74,20,69.01,25,686.3,31.01,0.04519,2.45E+04
1.74,20,75.01,25,745.7,31.08,0.04167,2.88E+04
1.74,20,81.01,25,805.6,30.93,0.03839,3.36E+04
1.74,20,87.01,25,865.2,30.49,0.03524,3.87E+04
1.74,20,93.01,25,925.1,30.23,0.03267,4.41E+04
1.74,20,99.01,25,985.1,30.05,0.03051,5.00E+04
1.74,20,105.1,25,946.5,27.35,0.02889,5.58E+04
1.74,20,111.1,25,886.4,27.28,0.03077,6.13E+04
1.74,20,117.1,25,827.1,26.55,0.0321,6.64E+04
1.74,20,123.1,25,767,25.82,0.03366,7.11E+04
1.74,20,129.1,25,707.6,25.6,0.03618,7.55E+04
1.74,20,135.1,25,647.6,25.33,0.03911,7.95E+04
1.74,20,141.1,25,588.2,23.94,0.0407,8.32E+04
1.74,20,147.1,25,528.3,23.67,0.0448,8.65E+04
1.74,20,153.1,25,468.8,21.32,0.04548,8.95E+04
1.74,20,159.1,25,408.8,20.18,0.04936,9.20E+04
1.74,20,165.1,25,349.3,18.93,0.05419,9.43E+04
1.74,20,171.1,25,289.4,11.74,0.04056,9.61E+04
1.74,20,177.1,25,229.9,11.09,0.04821,9.76E+04
1.74,20,183.1,25,170,9.96,0.0586,9.88E+04
1.74,20,189.1,25,110,8.721,0.07926,9.96E+04
1.74,20,195.1,25,50.56,7.35,0.1454,1.00E+05
1.74,30,1.004,25,9.443,38,4.024,19.01
1.74,30,7.007,25,68.9,50.63,0.7349,315.3
1.74,30,13.01,25,128.8,42.71,0.3315,974.9
1.74,30,19.01,25,188.3,41.08,0.2182,1991
1.74,30,25.01,25,248.3,41.57,0.1674,3370
1.74,30,31.01,25,308.2,43.5,0.1411,5109
1.74,30,37.01,25,367.7,46.72,0.1271,7203
1.74,30,43.01,25,427.7,47.43,0.1109,9663
1.74,30,49.01,25,487.1,48.25,0.09906,1.25E+04
1.74,30,55.01,25,547,48.54,0.08874,1.57E+04
1.74,30,61.01,25,606.5,51.25,0.0845,1.92E+04
1.74,30,67.01,25,666.4,50.09,0.07517,2.31E+04
1.74,30,73.01,25,725.9,51.9,0.0715,2.74E+04
1.74,30,79.01,25,785.9,52.77,0.06715,3.20E+04
1.74,30,85.01,25,845.3,53.71,0.06354,3.69E+04
1.74,30,91.01,25,905.3,55.47,0.06127,4.23E+04
1.74,30,97.01,25,964.8,56.16,0.05821,4.80E+04
1.74,30,103.1,25,966.3,53.54,0.0554,5.39E+04
1.74,30,109.1,25,906.8,51.59,0.05689,5.95E+04
1.74,30,115.1,25,846.9,49.73,0.05872,6.47E+04
1.74,30,121.1,25,787.3,48.55,0.06167,6.96E+04
1.74,30,127.1,25,727.4,47.28,0.065,7.41E+04
1.74,30,133.1,25,667.5,45.51,0.06818,7.82E+04
1.74,30,139.1,25,608,43.79,0.07202,8.20E+04
1.74,30,145.1,25,548.1,42.71,0.07793,8.55E+04
1.74,30,151.1,25,488.6,41.71,0.08537,8.85E+04
1.74,30,157.1,25,428.6,40.69,0.09493,9.12E+04
1.74,30,163.1,25,368.7,39.57,0.1073,9.36E+04
1.74,30,169.1,25,309.2,36.08,0.1167,9.55E+04
1.74,30,175.1,25,249.3,27.4,0.1099,9.72E+04
1.74,30,181.1,25,189.8,25.39,0.1338,9.84E+04
1.74,30,187.1,25,129.8,21.31,0.1642,9.93E+04
1.74,30,193.1,25,70.37,17.14,0.2436,9.99E+04
1.74,30,199.1,25,10.43,4.78,0.4585,1.00E+05
1.74,30,5.029,25,49.56,74,1.493,180
1.74,30,11.03,25,109,50.53,0.4635,718.7
1.74,30,17.03,25,169,46.2,0.2735,1619
1.74,30,23.03,25,228.5,46.39,0.2031,2880
1.74,30,29.03,25,288.4,47.63,0.1652,4497
1.74,30,35.03,25,348.3,53.23,0.1528,6479
1.74,30,41.03,25,407.8,52.95,0.1298,8815
1.74,30,47.03,25,467.8,53.51,0.1144,1.15E+04
1.74,30,53.03,25,527.2,57.08,0.1083,1.46E+04
1.74,30,59.03,25,587.2,57.59,0.09808,1.80E+04
1.74,30,65.03,25,646.6,59.01,0.09126,2.18E+04
1.74,30,71.03,25,706.5,60.57,0.08573,2.59E+04
1.74,30,77.03,25,766.1,61.73,0.08057,3.04E+04
1.74,30,83.03,25,826,62.59,0.07577,3.53E+04
1.74,30,89.03,25,885.5,63.55,0.07176,4.05E+04
1.74,30,95.03,25,945.5,64.6,0.06833,4.61E+04
1.74,30,101,25,986.2,63.46,0.06435,5.20E+04
1.74,30,107.1,25,926.7,59.39,0.06409,5.77E+04
1.74,30,113.1,25,866.7,57.68,0.06655,6.30E+04
1.74,30,119.1,25,807.2,55.98,0.06934,6.80E+04
1.74,30,125.1,25,747.2,54.13,0.07245,7.26E+04
1.74,30,131.1,25,687.8,52.85,0.07684,7.69E+04
1.74,30,137.1,25,627.8,50.81,0.08094,8.08E+04
1.74,30,143.1,25,568.4,49.09,0.08636,8.43E+04
1.74,30,149.1,25,508.5,47.85,0.09411,8.75E+04
1.74,30,155.1,25,448.5,45.44,0.1013,9.04E+04
1.74,30,161.1,25,389,44.53,0.1145,9.28E+04
1.74,30,167.1,25,329.1,42.04,0.1277,9.49E+04
1.74,30,173.1,25,269.6,32.88,0.122,9.67E+04
1.74,30,179.1,25,209.7,30.25,0.1443,9.81E+04
1.74,30,185.1,25,150.2,27.01,0.1798,9.91E+04
1.74,30,191.1,25,90.24,20.04,0.2221,9.97E+04
1.74,30,197.1,25,30.3,11.01,0.3635,1.00E+05
2.7,10,3.008,25,29.25,125.1,4.276,78.36
2.7,10,9.008,25,89.21,117.5,1.317,496.5
2.7,10,15.01,25,148.7,76.01,0.5113,1273
2.7,10,21.01,25,208.6,78.48,0.3762,2411
2.7,10,27.01,25,268.1,75.05,0.2799,3911
2.7,10,33.01,25,328,72.75,0.2218,5765
2.7,10,39.01,25,387.5,70.33,0.1815,7985
2.7,10,45.01,25,447.5,69.81,0.156,1.06E+04
2.7,10,51.01,25,506.9,69.44,0.137,1.35E+04
2.7,10,57.01,25,566.9,68.92,0.1216,1.68E+04
2.7,10,63.01,25,626.3,69.29,0.1106,2.05E+04
2.7,10,69.01,25,686.3,69.46,0.1012,2.45E+04
2.7,10,75.01,25,745.7,70.21,0.09414,2.88E+04
2.7,10,81.01,25,805.6,70.49,0.0875,3.36E+04
2.7,10,87.01,25,865.2,71.43,0.08256,3.87E+04
2.7,10,93.01,25,925.1,71.83,0.07764,4.41E+04
2.7,10,99.01,25,985.1,72.31,0.0734,5.00E+04
2.7,10,105.1,25,946.5,67.68,0.07151,5.58E+04
2.7,10,111.1,25,886.5,66.21,0.07469,6.13E+04
2.7,10,117.1,25,827,64.85,0.07842,6.64E+04
2.7,10,123.1,25,767.1,63.12,0.08229,7.11E+04
2.7,10,129.1,25,707.6,61.66,0.08715,7.55E+04
2.7,10,135.1,25,647.6,60.13,0.09284,7.95E+04
2.7,10,141.1,25,588.2,58.33,0.09917,8.32E+04
2.7,10,147.1,25,528.2,59.63,0.1129,8.65E+04
2.7,10,153.1,25,468.8,54.58,0.1164,8.94E+04
2.7,10,159.1,25,408.8,52.41,0.1282,9.20E+04
2.7,10,165.1,25,349.3,50.68,0.1451,9.42E+04
2.7,10,171.1,25,289.4,43.74,0.1512,9.61E+04
2.7,10,177.1,25,229.9,40.93,0.178,9.76E+04
2.7,10,183.1,25,170,36.77,0.2164,9.88E+04
2.7,10,189.1,25,110,29.04,0.2639,9.95E+04
2.7,10,195.1,25,50.56,18.09,0.3577,1.00E+05
2.7,10,1.005,25,9.45,60.9,6.445,19.36
2.7,10,7.008,25,68.89,100.4,1.457,316.6
2.7,10,13.01,25,128.8,84.78,0.658,974.9
2.7,10,19.01,25,188.3,71.78,0.3812,1991
2.7,10,25.01,25,248.3,69.86,0.2814,3370
2.7,10,31.01,25,308.2,67.79,0.22,5109
2.7,10,37.01,25,367.7,67.78,0.1843,7203
2.7,10,43.01,25,427.6,66.58,0.1557,9663
2.7,10,49.01,25,487.1,66.5,0.1365,1.25E+04
2.7,10,55.01,25,547,67.51,0.1234,1.57E+04
2.7,10,61.01,25,606.5,68.31,0.1126,1.92E+04
2.7,10,67.01,25,666.4,68.66,0.103,2.31E+04
2.7,10,73.01,25,725.9,69.63,0.09593,2.74E+04
2.7,10,79.01,25,785.8,69.62,0.08859,3.20E+04
2.7,10,85.01,25,845.3,70.07,0.08289,3.69E+04
2.7,10,91.01,25,905.3,70.7,0.07809,4.23E+04
2.7,10,97.01,25,964.8,70.68,0.07326,4.80E+04
2.7,10,103.1,25,966.4,67.01,0.06934,5.40E+04
2.7,10,109.1,25,906.8,65.23,0.07193,5.95E+04
2.7,10,115.1,25,846.8,63.51,0.075,6.48E+04
2.7,10,121.1,25,787.4,61.88,0.07859,6.96E+04
2.7,10,127.1,25,727.4,59.89,0.08233,7.41E+04
2.7,10,133.1,25,667.5,59.01,0.08841,7.83E+04
2.7,10,139.1,25,608,57.63,0.09478,8.21E+04
2.7,10,145.1,25,548.1,55.86,0.1019,8.55E+04
2.7,10,151.1,25,488.7,54.07,0.1106,8.86E+04
2.7,10,157.1,25,428.7,53.05,0.1237,9.13E+04
2.7,10,163.1,25,368.7,51.16,0.1388,9.36E+04
2.7,10,169.1,25,309.3,46.31,0.1498,9.56E+04
2.7,10,175.1,25,249.3,40.77,0.1635,9.72E+04
2.7,10,181.1,25,189.9,37.5,0.1975,9.85E+04
2.7,10,187.1,25,129.9,30.4,0.234,9.94E+04
2.7,10,193.1,25,70.45,20.86,0.2961,9.99E+04
2.7,10,199.1,25,10.5,5.86,0.5583,1.00E+05
2.7,20,5.026,25,49.06,985.5,20.09,178
2.7,20,11.03,25,108.5,800.3,7.377,712.8
2.7,20,17.03,25,168.5,598.6,3.553,1613
2.7,20,23.03,25,228.4,612.8,2.683,2869
2.7,20,29.03,25,287.9,396.6,1.378,4488
2.7,20,35.03,25,347.8,359.4,1.033,6467
2.7,20,41.02,25,407.3,234.3,0.5754,8801
2.7,20,47.02,25,467.3,191.5,0.4099,1.15E+04
2.7,20,53.02,25,526.8,167.1,0.3172,1.46E+04
2.7,20,59.03,25,586.7,153.9,0.2623,1.80E+04
2.7,20,65.02,25,646.6,147.2,0.2276,2.18E+04
2.7,20,71.02,25,706.1,144.7,0.2049,2.59E+04
2.7,20,77.02,25,766.1,138.9,0.1813,3.04E+04
2.7,20,83.02,25,825.6,132.8,0.1609,3.52E+04
2.7,20,89.02,25,885.4,128.5,0.1451,4.05E+04
2.7,20,95.02,25,945,123.3,0.1305,4.60E+04
2.7,20,101.1,25,986.1,120.7,0.1224,5.21E+04
2.7,20,107.1,25,926.1,115.5,0.1247,5.78E+04
2.7,20,113.1,25,866.6,111.2,0.1283,6.31E+04
2.7,20,119.1,25,806.7,106.7,0.1323,6.81E+04
2.7,20,125.1,25,746.7,104.2,0.1395,7.27E+04
2.7,20,131.1,25,687.3,104.3,0.1518,7.70E+04
2.7,20,137.1,25,627.3,98.98,0.1578,8.09E+04
2.7,20,143.1,25,567.8,92.6,0.1631,8.44E+04
2.7,20,149.1,25,507.9,84.15,0.1657,8.76E+04
2.7,20,155.1,25,448.5,80.36,0.1792,9.04E+04
2.7,20,161.1,25,388.5,75.67,0.1948,9.29E+04
2.7,20,167.1,25,328.5,70.83,0.2156,9.50E+04
2.7,20,173.1,25,269.1,65.11,0.242,9.67E+04
2.7,20,179.1,25,209.1,52.96,0.2533,9.81E+04
2.7,20,185.1,25,149.6,42.93,0.2869,9.91E+04
2.7,20,191.1,25,89.69,49.8,0.5553,9.98E+04
2.7,20,197.1,25,30.23,33.65,1.113,1.00E+05
2.7,20,3.009,25,29.22,349.8,11.97,77.7
2.7,20,9.008,25,89.2,185.1,2.075,496.5
2.7,20,15.01,25,148.7,171,1.15,1273
2.7,20,21.01,25,208.6,131.2,0.6287,2411
2.7,20,27.01,25,268.1,124.9,0.4659,3911
2.7,20,33.01,25,328,128,0.3901,5765
2.7,20,39.01,25,387.5,124.2,0.3205,7985
2.7,20,45.01,25,447.5,117.5,0.2625,1.06E+04
2.7,20,51.01,25,506.9,109.7,0.2163,1.35E+04
2.7,20,57.01,25,566.9,105,0.1852,1.68E+04
2.7,20,63.01,25,626.3,101.8,0.1625,2.05E+04
2.7,20,69.01,25,686.3,99.22,0.1446,2.45E+04
2.7,20,75.01,25,745.7,97.39,0.1306,2.88E+04
2.7,20,81.01,25,805.6,96.08,0.1193,3.36E+04
2.7,20,87.01,25,865.2,94.29,0.109,3.87E+04
2.7,20,93.01,25,925.1,92.7,0.1002,4.41E+04
2.7,20,99.01,25,985.1,91.12,0.0925,5.00E+04
2.7,20,105.1,25,946.5,85.94,0.0908,5.58E+04
2.7,20,111.1,25,886.4,83.35,0.09403,6.13E+04
2.7,20,117.1,25,827,81.4,0.09843,6.64E+04
2.7,20,123.1,25,767.1,79.72,0.1039,7.11E+04
2.7,20,129.1,25,707.6,78.09,0.1104,7.55E+04
2.7,20,135.1,25,647.6,77.02,0.1189,7.95E+04
2.7,20,141.1,25,588.1,74.19,0.1261,8.32E+04
2.7,20,147.1,25,528.2,71.78,0.1359,8.65E+04
2.7,20,153.1,25,468.8,72.08,0.1538,8.95E+04
2.7,20,159.1,25,408.8,69.88,0.1709,9.20E+04
2.7,20,165.1,25,349.3,66.37,0.19,9.43E+04
2.7,20,171.1,25,289.4,60.79,0.21,9.61E+04
2.7,20,177.1,25,229.9,57.21,0.2488,9.76E+04
2.7,20,183.1,25,170,50.3,0.2959,9.88E+04
2.7,20,189.1,25,110.5,36.5,0.3302,9.96E+04
2.7,20,195.1,25,50.57,23.03,0.4554,1.00E+05
2.7,20,1.004,25,9.522,167.8,17.62,19.06
2.7,20,7.007,25,68.89,125.2,1.818,315.3
2.7,20,13.01,25,128.9,100.4,0.7791,974.9
2.7,20,19.01,25,188.3,96.74,0.5138,1991
2.7,20,25.01,25,248.3,110,0.4431,3370
2.7,20,31.01,25,308.2,111.2,0.3609,5109
2.7,20,37.01,25,367.7,109.2,0.297,7203
2.7,20,43.03,25,427.7,104.5,0.2444,9678
2.7,20,49.01,25,487.1,100.9,0.2072,1.25E+04
2.7,20,55.03,25,547,97.45,0.1781,1.57E+04
2.7,20,61.03,25,607,93.83,0.1546,1.92E+04
2.7,20,67.03,25,666.4,92.56,0.1389,2.31E+04
2.7,20,73.03,25,726.4,91.11,0.1254,2.74E+04
2.7,20,79.03,25,785.9,89.01,0.1133,3.20E+04
2.7,20,85.03,25,845.8,87.74,0.1037,3.70E+04
2.7,20,91.03,25,905.7,86.5,0.0955,4.23E+04
2.7,20,97.03,25,965.3,85.53,0.08861,4.80E+04
2.7,20,103.1,25,966.3,81.44,0.08428,5.39E+04
2.7,20,109.1,25,906.8,79.56,0.08773,5.95E+04
2.7,20,115.1,25,846.8,77.56,0.09159,6.47E+04
2.7,20,121.1,25,786.9,75.74,0.09625,6.96E+04
2.7,20,127.1,25,727.4,73.87,0.1015,7.41E+04
2.7,20,133.1,25,667.5,72.37,0.1084,7.83E+04
2.7,20,139.1,25,608.1,71.75,0.118,8.20E+04
2.7,20,145.1,25,548.1,69.8,0.1274,8.55E+04
2.7,20,151.1,25,488.7,68.2,0.1396,8.85E+04
2.7,20,157.1,25,428.7,66.65,0.1555,9.12E+04
2.7,20,163.1,25,368.7,64.9,0.176,9.36E+04
2.7,20,169.1,25,309.3,60.86,0.1968,9.55E+04
2.7,20,175.1,25,249.3,56.62,0.2271,9.72E+04
2.7,20,181.1,25,189.9,51.84,0.273,9.84E+04
2.7,20,187.1,25,129.9,44,0.3387,9.93E+04
2.7,20,193.1,25,70.43,25.86,0.3672,9.99E+04
2.7,20,199.1,25,10.48,6.711,0.6404,1.00E+05
2.7,20,5.008,25,49.06,102.3,2.085,178
2.7,20,11.01,25,109,82.16,0.7535,714.8
2.7,20,17.01,25,168.5,59.29,0.3519,1613
2.7,20,23.01,25,228.4,68.68,0.3007,2869
2.7,20,29.01,25,287.9,66.32,0.2304,4488
2.7,20,35.01,25,347.9,66.5,0.1912,6467
2.7,20,41.01,25,407.3,63.29,0.1554,8801
2.7,20,47.01,25,467.3,60.93,0.1304,1.15E+04
2.7,20,53.01,25,526.8,61.66,0.117,1.46E+04
2.7,20,59.01,25,586.7,60.27,0.1027,1.80E+04
2.7,20,65.01,25,646.6,59.85,0.09255,2.18E+04
2.7,20,71.01,25,706,58.58,0.08297,2.59E+04
2.7,20,77.01,25,766.1,58.32,0.07613,3.04E+04
2.7,20,83.01,25,825.5,57.67,0.06986,3.52E+04
2.7,20,89.01,25,885.5,57.61,0.06506,4.05E+04
2.7,20,95.01,25,945,57.45,0.0608,4.60E+04
2.7,20,101,25,986.1,55.12,0.0559,5.20E+04
2.7,20,107.1,25,926.6,52.98,0.05717,5.77E+04
2.7,20,113.1,25,866.7,52.2,0.06023,6.30E+04
2.7,20,119.1,25,807.2,51.14,0.06335,6.80E+04
2.7,20,125.1,25,747.2,50.2,0.06718,7.26E+04
2.7,20,131.1,25,687.7,49.96,0.07264,7.69E+04
2.7,20,137.1,25,627.8,48.48,0.07721,8.08E+04
2.7,20,143.1,25,568.4,47.59,0.08373,8.43E+04
2.7,20,149.1,25,508.4,46.66,0.09178,8.75E+04
2.7,20,155.1,25,448.9,46.01,0.1025,9.04E+04
2.7,20,161.1,25,389,45.08,0.1159,9.28E+04
2.7,20,167.1,25,329,44.16,0.1342,9.49E+04
2.7,20,173.1,25,269.6,36.02,0.1336,9.67E+04
2.7,20,179.1,25,209.6,34.77,0.1659,9.80E+04
2.7,20,185.1,25,150.2,32.54,0.2167,9.91E+04
2.7,20,191.1,25,90.2,26.44,0.2932,9.97E+04
2.7,20,197.1,25,30.25,12.8,0.4232,1.00E+05
2.7,20,3.008,25,29.25,61.96,2.119,77.73
2.7,20,9.008,25,88.71,43.17,0.4867,494.9
2.7,20,15.01,25,148.7,51.03,0.3432,1273
2.7,20,21.01,25,208.6,45.21,0.2167,2411
2.7,20,27.01,25,268.1,47.78,0.1782,3911
2.7,20,33.01,25,328,51.95,0.1584,5765
2.7,20,39.01,25,387.5,48.91,0.1262,7985
2.7,20,45.01,25,447.5,46.79,0.1046,1.06E+04
2.7,20,51.01,25,506.9,45.78,0.09031,1.35E+04
2.7,20,57.01,25,566.9,44.95,0.0793,1.68E+04
2.7,20,63.01,25,626.3,44.36,0.07083,2.05E+04
2.7,20,69.01,25,686.3,43.54,0.06344,2.45E+04
2.7,20,75.01,25,745.7,43.03,0.05771,2.88E+04
2.7,20,81.01,25,805.7,43.26,0.0537,3.36E+04
2.7,20,87.01,25,865.2,42.56,0.04919,3.87E+04
2.7,20,93.01,25,925.1,42.41,0.04584,4.41E+04
2.7,20,99.01,25,985.1,42.53,0.04317,5.00E+04
2.7,20,105.1,25,946.5,39.37,0.04159,5.58E+04
2.7,20,111.1,25,886.4,38.77,0.04373,6.13E+04
2.7,20,117.1,25,827.1,37.75,0.04564,6.64E+04
2.7,20,123.1,25,767.1,38.05,0.04961,7.11E+04
2.7,20,129.1,25,707.6,37.63,0.05318,7.55E+04
2.7,20,135.1,25,647.6,37.2,0.05744,7.95E+04
2.7,20,141.1,25,588.1,36.73,0.06245,8.32E+04
2.7,20,147.1,25,528.2,35.02,0.0663,8.65E+04
2.7,20,153.1,25,468.8,36.05,0.07691,8.95E+04
2.7,20,159.1,25,408.8,35.91,0.08784,9.20E+04
2.7,20,165.1,25,349.3,34.27,0.0981,9.43E+04
2.7,20,171.1,25,289.4,25.38,0.08769,9.61E+04
2.7,20,177.1,25,229.9,24.14,0.105,9.76E+04
2.7,20,183.1,25,170,22.61,0.133,9.88E+04
2.7,20,189.1,25,110.5,20.07,0.1816,9.95E+04
2.7,20,195.1,25,50.56,11.47,0.2268,1.00E+05
2.7,30,1.004,25,9.443,28.83,3.053,19.03
2.7,30,7.008,25,68.9,51.98,0.7544,315.3
2.7,30,13.01,25,128.8,42.35,0.3287,974.9
2.7,30,19.01,25,188.3,41.31,0.2194,1991
2.7,30,25.01,25,248.3,38,0.153,3370
2.7,30,31.01,25,308.2,41.19,0.1336,5109
2.7,30,37.01,25,367.7,43.55,0.1185,7203
2.7,30,43.01,25,427.6,44.27,0.1035,9663
2.7,30,49.01,25,487.1,43.82,0.08996,1.25E+04
2.7,30,55.01,25,547.1,44.25,0.08088,1.57E+04
2.7,30,61.01,25,606.5,45.71,0.07537,1.92E+04
2.7,30,67.01,25,666.4,45.7,0.06857,2.31E+04
2.7,30,73.01,25,725.9,46.79,0.06446,2.74E+04
2.7,30,79.01,25,785.9,47.1,0.05993,3.20E+04
2.7,30,85.01,25,845.3,48.26,0.05708,3.69E+04
2.7,30,91.01,25,905.2,48.77,0.05387,4.23E+04
2.7,30,97.01,25,964.8,49.66,0.05148,4.80E+04
2.7,30,103.1,25,966.3,46.89,0.04852,5.40E+04
2.7,30,109.1,25,906.8,46.46,0.05123,5.95E+04
2.7,30,115.1,25,846.9,45.55,0.05378,6.48E+04
2.7,30,121.1,25,787.4,44.68,0.05675,6.96E+04
2.7,30,127.1,25,727.5,44.77,0.06154,7.41E+04
2.7,30,133.1,25,667.5,43.59,0.0653,7.83E+04
2.7,30,139.1,25,608,41.53,0.06831,8.21E+04
2.7,30,145.1,25,548.1,41.77,0.0762,8.55E+04
2.7,30,151.1,25,488.7,40.7,0.08329,8.86E+04
2.7,30,157.1,25,428.7,40,0.09331,9.13E+04
2.7,30,163.1,25,368.7,39.16,0.1062,9.36E+04
2.7,30,169.1,25,309.2,35.82,0.1158,9.56E+04
2.7,30,175.1,25,249.3,27.11,0.1088,9.72E+04
2.7,30,181.1,25,189.9,25.35,0.1335,9.85E+04
2.7,30,187.1,25,129.9,21.95,0.169,9.94E+04
2.7,30,193.1,25,70.42,17.03,0.2419,9.99E+04
2.7,30,199.1,25,10.48,4.062,0.3876,1.00E+05
2.7,30,5.008,25,49.07,48.69,0.9923,177
2.7,30,11.01,25,109,43.06,0.395,714.8
2.7,30,17.01,25,168.5,43.21,0.2565,1613
2.7,30,23.01,25,228.4,40.28,0.1763,2869
2.7,30,29.01,25,287.9,38,0.132,4488
2.7,30,35.01,25,347.8,44.95,0.1292,6467
2.7,30,41.01,25,407.3,44.18,0.1085,8801
2.7,30,47.01,25,467.3,45.77,0.09795,1.15E+04
2.7,30,53.01,25,526.7,44.52,0.08452,1.46E+04
2.7,30,59.01,25,586.7,45.6,0.07774,1.80E+04
2.7,30,65.01,25,646.6,46.4,0.07177,2.18E+04
2.7,30,71.01,25,706,47.36,0.06708,2.59E+04
2.7,30,77.01,25,766.1,47.42,0.06189,3.04E+04
2.7,30,83.01,25,825.5,48.49,0.05874,3.52E+04
2.7,30,89.01,25,885.4,48.76,0.05507,4.05E+04
2.7,30,95.01,25,944.9,49.84,0.05274,4.60E+04
2.7,30,101,25,986.1,48.96,0.04965,5.20E+04
2.7,30,107.1,25,926.1,47.21,0.05098,5.77E+04
2.7,30,113.1,25,866.7,45.87,0.05293,6.30E+04
2.7,30,119.1,25,806.6,45.75,0.05672,6.80E+04
2.7,30,125.1,25,746.7,44.56,0.05967,7.27E+04
2.7,30,131.1,25,687.3,43.74,0.06364,7.69E+04
2.7,30,137.1,25,627.3,43.18,0.06883,8.08E+04
2.7,30,143.1,25,567.9,42.02,0.07399,8.43E+04
2.7,30,149.1,25,507.9,41.52,0.08175,8.75E+04
2.7,30,155.1,25,448.4,40.35,0.08997,9.03E+04
2.7,30,161.1,25,388.5,39.72,0.1023,9.28E+04
2.7,30,167.1,25,329,37.92,0.1153,9.49E+04
2.7,30,173.1,25,269.1,29.42,0.1093,9.67E+04
2.7,30,179.1,25,209.6,25.67,0.1225,9.80E+04
2.7,30,185.1,25,149.7,23.5,0.157,9.91E+04
2.7,30,191.1,25,90.19,18.87,0.2092,9.97E+04
2.7,30,197.1,25,30.25,9.715,0.3212,1.00E+05
2.7,30,199.1,25,10.43,4.501,0.4317,1.00E+05