File: Test.csv
DensityX,Composition,Time s,Temperature °C,Shear Rate 1/s,Shear Stress Pa,Instantaneous Viscosity Pas,Strain
4.506,10,1.004,25,9.665,661.1,68.4,19.27
4.506,10,5.013,25,49.09,1331,27.11,177.7
4.506,10,9.012,25,89.02,995.9,11.19,496.6
4.506,10,13.01,25,128.8,1397,10.84,972.2
4.506,10,17.01,25,168.1,1264,7.52,1613
4.506,10,21.01,25,208.3,1358,6.522,2410
4.506,10,25.01,25,248.3,1158,4.665,3368
4.506,10,29.01,25,287.7,1113,3.87,4487
4.506,10,33.01,25,328.3,1094,3.333,5766
4.506,10,37.01,25,367.7,921.4,2.506,7204
4.506,10,41.01,25,407.3,946.3,2.323,8800
4.506,10,45.01,25,447.4,956.6,2.138,1.06E+04
4.506,10,49.01,25,487,1028,2.111,1.25E+04
4.506,10,53.01,25,526.8,954.4,1.812,1.46E+04
4.506,10,57.01,25,566.8,1065,1.879,1.68E+04
4.506,10,61.01,25,606.6,1258,2.074,1.92E+04
4.506,10,65.01,25,646.5,1240,1.918,2.18E+04
4.506,10,69.01,25,686.2,1060,1.545,2.45E+04
4.506,10,73.01,25,725.8,1006,1.385,2.74E+04
4.506,10,77.01,25,766.2,1142,1.491,3.04E+04
4.506,10,81.01,25,805.8,1135,1.408,3.36E+04
4.506,10,85.01,25,845.3,979.3,1.159,3.69E+04
4.506,10,89.01,25,885.6,1068,1.205,4.05E+04
4.506,10,93.01,25,925.2,1123,1.214,4.41E+04
4.506,10,97.01,25,964.7,1151,1.193,4.80E+04
4.506,10,101.1,25,985.6,1108,1.124,5.20E+04
4.506,10,105.1,25,946.4,949.5,1.003,5.58E+04
4.506,10,109.1,25,906.9,903.2,0.9959,5.95E+04
4.506,10,113.1,25,866.4,877.5,1.013,6.31E+04
4.506,10,117.1,25,827.1,851.4,1.029,6.64E+04
4.506,10,121.1,25,787,829.1,1.054,6.96E+04
4.506,10,125.1,25,746.7,875.8,1.173,7.27E+04
4.506,10,129.1,25,707,891.8,1.261,7.55E+04
4.506,10,133.1,25,667.5,1119,1.676,7.83E+04
4.506,10,137.1,25,627.3,962.8,1.535,8.08E+04
4.506,10,141.1,25,587.8,948.9,1.615,8.32E+04
4.506,10,145.1,25,548.3,1045,1.905,8.55E+04
4.506,10,149.1,25,508.3,1092,2.148,8.76E+04
4.506,10,153.1,25,468.3,963.9,2.059,8.95E+04
4.506,10,157.1,25,428.7,1044,2.436,9.12E+04
4.506,10,161.1,25,388.5,913.2,2.351,9.28E+04
4.506,10,165.1,25,348.8,870.5,2.496,9.43E+04
4.506,10,169.1,25,309.1,828.7,2.681,9.55E+04
4.506,10,173.1,25,269,1056,3.927,9.67E+04
4.506,10,177.1,25,229.6,868.5,3.782,9.76E+04
4.506,10,181.1,25,189.8,884.3,4.658,9.84E+04
4.506,10,185.1,25,149.8,866.5,5.784,9.91E+04
4.506,10,189.1,25,110,807.3,7.342,9.96E+04
4.506,10,193.1,25,70.37,740.9,10.53,9.99E+04
4.506,10,197.1,25,30.3,802.5,26.48,1.00E+05
4.506,10,1.004,25,9.64,417.8,43.34,19.1
4.506,10,5.008,25,49.06,211,4.302,177
4.506,10,9.008,25,88.71,195.8,2.207,494.9
4.506,10,13.01,25,128.9,186.7,1.449,974.9
4.506,10,17.01,25,168.5,156.7,0.9301,1613
4.506,10,21.01,25,208.5,163.3,0.7829,2411
4.506,10,25.01,25,248.3,140.7,0.5668,3370
4.506,10,29.01,25,287.9,182.6,0.6343,4488
4.506,10,33.01,25,328.1,173.4,0.5287,5765
4.506,10,37.01,25,367.7,122.6,0.3334,7203
4.506,10,41.01,25,407.3,117.6,0.2888,8801
4.506,10,45.01,25,447.4,112.2,0.2508,1.06E+04
4.506,10,49.01,25,487.1,108.7,0.2232,1.25E+04
4.506,10,53.01,25,526.7,109.2,0.2074,1.46E+04
4.506,10,57.01,25,566.9,107.7,0.19,1.68E+04
4.506,10,61.01,25,606.5,106,0.1747,1.92E+04
4.506,10,65.03,25,646.6,106.4,0.1646,2.18E+04
4.506,10,69.03,25,686.8,106.3,0.1548,2.45E+04
4.506,10,73.01,25,725.9,106.7,0.1469,2.74E+04
4.506,10,77.01,25,766.1,107.5,0.1404,3.04E+04
4.506,10,81.03,25,806.2,107.1,0.1329,3.36E+04
4.506,10,85.01,25,845.3,106.1,0.1255,3.69E+04
4.506,10,89.03,25,885.5,107.8,0.1217,4.05E+04
4.506,10,93.03,25,925.6,106.6,0.1151,4.42E+04
4.506,10,97.01,25,964.8,106.7,0.1106,4.80E+04
4.506,10,101.1,25,986.2,104.3,0.1057,5.20E+04
4.506,10,105.1,25,946.5,109.4,0.1156,5.59E+04
4.506,10,109.1,25,906.4,101.5,0.112,5.96E+04
4.506,10,113.1,25,866.7,99.28,0.1145,6.31E+04
4.506,10,117.1,25,827.1,98.36,0.1189,6.64E+04
4.506,10,121.1,25,787,95.48,0.1213,6.96E+04
4.506,10,125.1,25,747.3,94.01,0.1258,7.27E+04
4.506,10,129.1,25,707.1,94.07,0.133,7.56E+04
4.506,10,133.1,25,667.5,88.53,0.1326,7.83E+04
4.506,10,137.1,25,627.9,87.53,0.1394,8.09E+04
4.506,10,141.1,25,587.7,88.56,0.1507,8.33E+04
4.506,10,145.1,25,548.2,83.97,0.1532,8.55E+04
4.506,10,149.1,25,508.5,81.84,0.1609,8.76E+04
4.506,10,153.1,25,468.3,80.77,0.1725,8.95E+04
4.506,10,157.1,25,428.7,78.01,0.182,9.13E+04
4.506,10,161.1,25,389.1,76.22,0.1959,9.29E+04
4.506,10,165.1,25,348.9,73.55,0.2108,9.43E+04
4.506,10,169.1,25,309.3,71.66,0.2317,9.56E+04
4.506,10,173.1,25,269.7,64.97,0.2409,9.67E+04
4.506,10,177.1,25,229.5,59.33,0.2585,9.77E+04
4.506,10,181.1,25,189.9,54.89,0.2891,9.85E+04
4.506,10,185.1,25,150.2,47.49,0.3161,9.91E+04
4.506,10,189.1,25,110.1,40.15,0.3646,9.96E+04
4.506,10,193.1,25,70.46,31.36,0.445,9.99E+04
4.506,10,197.1,25,30.33,20.78,0.6853,1.00E+05
4.506,20,1.005,25,9.524,117.7,12.36,19.04
4.506,20,5.007,25,49.08,56.48,1.151,176.9
4.506,20,9.008,25,88.58,75.92,0.8571,494.9
4.506,20,13.01,25,128.8,44.7,0.347,972.6
4.506,20,17.01,25,168.5,45.52,0.2702,1613
4.506,20,21.01,25,208.6,42.97,0.206,2411
4.506,20,25.01,25,248.3,37.95,0.1529,3370
4.506,20,29.01,25,287.9,37.78,0.1312,4488
4.506,20,33.01,25,328,44.65,0.1361,5765
4.506,20,37.01,25,367.7,42.43,0.1154,7203
4.506,20,41.01,25,407.3,41.51,0.1019,8801
4.506,20,45.01,25,447.4,43.5,0.09723,1.06E+04
4.506,20,49.01,25,487.1,44.09,0.09051,1.25E+04
4.506,20,53.01,25,526.8,44.98,0.08539,1.46E+04
4.506,20,57.01,25,566.9,42.34,0.07468,1.68E+04
4.506,20,61.01,25,606.5,43.17,0.07119,1.92E+04
4.506,20,65.01,25,646.6,42.84,0.06625,2.18E+04
4.506,20,69.01,25,686.3,43.94,0.06403,2.45E+04
4.506,20,73.01,25,725.9,42.26,0.05822,2.74E+04
4.506,20,77.01,25,766.1,43.02,0.05615,3.04E+04
4.506,20,81.01,25,805.8,42.9,0.05324,3.36E+04
4.506,20,85.01,25,845.3,42.83,0.05066,3.69E+04
4.506,20,89.01,25,885.5,42.71,0.04823,4.05E+04
4.506,20,93.01,25,925.1,42.82,0.04629,4.41E+04
4.506,20,97.01,25,964.8,42.53,0.04408,4.80E+04
4.506,20,101,25,986.1,40.98,0.04155,5.20E+04
4.506,20,105.1,25,946.5,39.89,0.04214,5.58E+04
4.506,20,109.1,25,906.8,39.58,0.04365,5.95E+04
4.506,20,113.1,25,866.7,38.81,0.04478,6.31E+04
4.506,20,117.1,25,827,38.16,0.04614,6.64E+04
4.506,20,121.1,25,787.4,37.88,0.04811,6.96E+04
4.506,20,125.1,25,746.7,36.96,0.0495,7.27E+04
4.506,20,129.1,25,707.6,36.57,0.05168,7.55E+04
4.506,20,133.1,25,667.4,36.77,0.05509,7.82E+04
4.506,20,137.1,25,627.3,36.22,0.05773,8.08E+04
4.506,20,141.1,25,588.2,34.95,0.05942,8.32E+04
4.506,20,145.1,25,548.1,34.56,0.06306,8.55E+04
4.506,20,149.1,25,507.9,34.37,0.06766,8.75E+04
4.506,20,153.1,25,468.8,33.38,0.07121,8.95E+04
4.506,20,157.1,25,428.7,32.96,0.0769,9.12E+04
4.506,20,161.1,25,388.5,32.32,0.08319,9.28E+04
4.506,20,165.1,25,349.4,31.41,0.08992,9.43E+04
4.506,20,169.1,25,309.2,25.79,0.0834,9.55E+04
4.506,20,173.1,25,269.1,21.47,0.07979,9.67E+04
4.506,20,177.1,25,229.4,19.46,0.08479,9.76E+04
4.506,20,181.1,25,189.8,18.21,0.09591,9.84E+04
4.506,20,185.1,25,149.7,17.05,0.1139,9.91E+04
4.506,20,189.1,25,110,15.44,0.1404,9.96E+04
4.506,20,193.1,25,70.4,12.68,0.1801,9.99E+04
4.506,20,197.1,25,30.26,8.731,0.2885,1.00E+05
4.506,20,1.01,25,9.516,160.8,16.9,19.36
4.506,20,5.008,25,49.06,113.6,2.316,177
4.506,20,9.012,25,88.71,123.6,1.394,494.8
4.506,20,13.01,25,128.8,164.2,1.275,974.9
4.506,20,17.01,25,168.5,44.92,0.2666,1613
4.506,20,21.01,25,208.6,45.9,0.22,2411
4.506,20,25.01,25,248.3,46.39,0.1868,3370
4.506,20,29.01,25,287.9,76.41,0.2654,4488
4.506,20,33.01,25,328,98.63,0.3007,5766
4.506,20,37.01,25,367.6,105.9,0.288,7203
4.506,20,41.01,25,407.4,92.89,0.228,8801
4.506,20,45.01,25,447.4,105.6,0.236,1.06E+04
4.506,20,49.01,25,487.1,69.31,0.1423,1.25E+04
4.506,20,53.01,25,526.8,70.27,0.1334,1.46E+04
4.506,20,57.01,25,566.9,64.28,0.1134,1.68E+04
4.506,20,61.01,25,606.5,65.75,0.1084,1.92E+04
4.506,20,65.01,25,646.6,65.71,0.1016,2.18E+04
4.506,20,69.01,25,686.3,62.95,0.09172,2.45E+04
4.506,20,73.01,25,725.9,63.48,0.08746,2.74E+04
4.506,20,77.01,25,766.1,56.65,0.07395,3.04E+04
4.506,20,81.01,25,805.7,50.5,0.06268,3.36E+04
4.506,20,85.01,25,845.4,53.49,0.06328,3.69E+04
4.506,20,89.01,25,885.5,54.38,0.06141,4.05E+04
4.506,20,93.01,25,925.2,49.57,0.05358,4.41E+04
4.506,20,97.01,25,964.8,58.06,0.06018,4.80E+04
4.506,20,101,25,986.1,62.01,0.06289,5.20E+04
4.506,20,105.1,25,946.4,58.13,0.06143,5.58E+04
4.506,20,109.1,25,906.8,58.42,0.06442,5.95E+04
4.506,20,113.1,25,866.7,47.71,0.05505,6.30E+04
4.506,20,117.1,25,827,45.38,0.05488,6.64E+04
4.506,20,121.1,25,787.4,43.87,0.05572,6.96E+04
4.506,20,125.1,25,747.2,44.25,0.05922,7.26E+04
4.506,20,129.1,25,707.5,44.54,0.06295,7.55E+04
4.506,20,133.1,25,667.5,47.29,0.07085,7.82E+04
4.506,20,137.1,25,627.8,45.98,0.07325,8.08E+04
4.506,20,141.1,25,588.1,46.56,0.07916,8.32E+04
4.506,20,145.1,25,548,45.62,0.08325,8.55E+04
4.506,20,149.1,25,508.4,39.89,0.07846,8.75E+04
4.506,20,153.1,25,468.3,39.75,0.08488,8.95E+04
4.506,20,157.1,25,428.6,40.75,0.09507,9.12E+04
4.506,20,161.1,25,389,38.12,0.098,9.28E+04
4.506,20,165.1,25,349.3,38.13,0.1092,9.43E+04
4.506,20,169.1,25,309.2,40.79,0.1319,9.55E+04
4.506,20,173.1,25,269.6,33.68,0.1249,9.67E+04
4.506,20,177.1,25,229.4,32.76,0.1428,9.76E+04
4.506,20,181.1,25,189.8,29.33,0.1545,9.84E+04
4.506,20,185.1,25,150.2,29.51,0.1965,9.91E+04
4.506,20,189.1,25,110,26.75,0.2432,9.96E+04
4.506,20,193.1,25,70.38,23.12,0.3285,9.99E+04
4.506,20,197.1,25,30.24,11.39,0.3766,1.00E+05
4.506,30,1.005,25,9.458,65.7,6.946,19.39
4.506,30,5.007,25,49.07,56.49,1.151,178
4.506,30,9.007,25,88.71,68.18,0.7686,496.5
4.506,30,13.01,25,128.9,63.84,0.4954,974.9
4.506,30,17.01,25,168.5,58.04,0.3445,1613
4.506,30,21.01,25,208.6,53.1,0.2546,2411
4.506,30,25.01,25,248.3,47.56,0.1915,3370
4.506,30,29.01,25,287.9,44.44,0.1543,4488
4.506,30,33.01,25,328,49.86,0.152,5765
4.506,30,37.01,25,367.7,45.3,0.1232,7203
4.506,30,41.01,25,407.3,46.82,0.115,8801
4.506,30,45.01,25,447.5,45.69,0.1021,1.06E+04
4.506,30,49.01,25,487.1,44.14,0.09061,1.25E+04
4.506,30,53.01,25,526.7,43.77,0.0831,1.46E+04
4.506,30,57.01,25,566.9,44.57,0.07862,1.68E+04
4.506,30,61.01,25,606.5,44.05,0.07264,1.92E+04
4.506,30,65.01,25,646.6,43.57,0.06738,2.18E+04
4.506,30,69.01,25,686.2,43.38,0.06322,2.45E+04
4.506,30,73.01,25,725.9,43.02,0.05927,2.74E+04
4.506,30,77.01,25,766,44.55,0.05816,3.04E+04
4.506,30,81.01,25,805.6,44.71,0.05549,3.36E+04
4.506,30,85.01,25,845.3,44.42,0.05255,3.69E+04
4.506,30,89.01,25,885.4,45.25,0.05111,4.05E+04
4.506,30,93.01,25,925.1,44.57,0.04818,4.41E+04
4.506,30,97.01,25,964.8,45,0.04665,4.80E+04
4.506,30,101,25,986.1,43.48,0.04409,5.20E+04
4.506,30,105.1,25,946.5,41.67,0.04403,5.58E+04
4.506,30,109.1,25,906.4,40.99,0.04522,5.95E+04
4.506,30,113.1,25,866.6,41.23,0.04758,6.30E+04
4.506,30,117.1,25,827,40.97,0.04953,6.64E+04
4.506,30,121.1,25,786.9,39.86,0.05066,6.96E+04
4.506,30,125.1,25,747.2,38.94,0.05211,7.26E+04
4.506,30,129.1,25,707.5,43.28,0.06117,7.55E+04
4.506,30,133.1,25,667.4,38.02,0.05697,7.83E+04
4.506,30,137.1,25,627.8,37.86,0.0603,8.08E+04
4.506,30,141.1,25,588.2,38.32,0.06514,8.32E+04
4.506,30,145.1,25,548.1,36.93,0.06738,8.55E+04
4.506,30,149.1,25,508.4,36.37,0.07154,8.75E+04
4.506,30,153.1,25,468.8,35.97,0.07673,8.95E+04
4.506,30,157.1,25,428.6,35.2,0.08213,9.12E+04
4.506,30,161.1,25,389,34.84,0.08956,9.28E+04
4.506,30,165.1,25,349.2,47.23,0.1353,9.43E+04
4.506,30,169.1,25,309.2,30.24,0.0978,9.56E+04
4.506,30,173.1,25,269.6,25.42,0.09429,9.67E+04
4.506,30,177.1,25,229.4,22.36,0.09746,9.76E+04
4.506,30,181.1,25,189.8,20.53,0.1082,9.84E+04
4.506,30,185.1,25,150.2,20.02,0.1334,9.91E+04
4.506,30,189.1,25,110,18.33,0.1666,9.96E+04
4.506,30,193.1,25,69.89,13.5,0.1932,9.99E+04
4.506,30,197.1,25,30.25,13.29,0.4394,1.00E+05
4.506,30,1.005,25,9.641,705.5,73.17,19.74
4.506,30,5.028,25,48.98,871.6,17.79,177.5
4.506,30,9.028,25,89.25,1143,12.81,500.4
4.506,30,13.01,25,128.8,580.8,4.51,975
4.506,30,17.03,25,168.5,477.5,2.834,1613
4.506,30,21.03,25,208.6,436.5,2.093,2419
4.506,30,25.01,25,248.2,511.1,2.06,3369
4.506,30,29.03,25,287.9,460.6,1.599,4487
4.506,30,33.03,25,328,417.8,1.274,5777
4.506,30,37.01,25,367.7,449.9,1.224,7203
4.506,30,41.03,25,407.4,438.2,1.076,8801
4.506,30,45.03,25,447.5,490.4,1.096,1.06E+04
4.506,30,49.01,25,487.1,504.6,1.036,1.25E+04
4.506,30,53.03,25,526.8,434.1,0.824,1.46E+04
4.506,30,57.03,25,566.9,420.3,0.7414,1.68E+04
4.506,30,61.01,25,606.5,415.5,0.6851,1.92E+04
4.506,30,65.03,25,646.6,416.9,0.6448,2.18E+04
4.506,30,69.03,25,686.7,412.6,0.6008,2.45E+04
4.506,30,73.01,25,725.9,396.4,0.5462,2.74E+04
4.506,30,77.03,25,766,471.3,0.6152,3.04E+04
4.506,30,81.03,25,805.9,643.1,0.798,3.36E+04
4.506,30,85.01,25,845.3,994.5,1.176,3.69E+04
4.506,30,89.03,25,885.4,865,0.977,4.04E+04
4.506,30,93.03,25,925.4,909.2,0.9825,4.42E+04
4.506,30,97.01,25,964.8,752.4,0.7798,4.80E+04
4.506,30,101.1,25,986.2,645,0.654,5.20E+04
4.506,30,105.1,25,946.5,560.7,0.5923,5.58E+04
4.506,30,109.1,25,906.4,525.4,0.5797,5.95E+04
4.506,30,113.1,25,866.2,522.8,0.6036,6.31E+04
4.506,30,117.1,25,827.1,592.9,0.7168,6.64E+04
4.506,30,121.1,25,787.5,641.8,0.815,6.96E+04
4.506,30,125.1,25,746.8,651.3,0.872,7.27E+04
4.506,30,129.1,25,707.1,536.4,0.7586,7.55E+04
4.506,30,133.1,25,667.5,529,0.7926,7.83E+04
4.506,30,137.1,25,627.3,590.8,0.9418,8.08E+04
4.506,30,141.1,25,587.7,572.1,0.9734,8.32E+04
4.506,30,145.1,25,548.2,633.9,1.156,8.55E+04
4.506,30,149.1,25,508,643.9,1.268,8.76E+04
4.506,30,153.1,25,468.3,573.4,1.224,8.95E+04
4.506,30,157.1,25,428.7,547.4,1.277,9.12E+04
4.506,30,161.1,25,388.6,577.4,1.486,9.28E+04
4.506,30,165.1,25,348.9,584.4,1.675,9.43E+04
4.506,30,169.1,25,309.2,558.2,1.805,9.56E+04
4.506,30,173.1,25,269.1,558,2.073,9.67E+04
4.506,30,177.1,25,229.5,545.9,2.378,9.76E+04
4.506,30,181.1,25,189.9,524,2.76,9.84E+04
4.506,30,185.1,25,149.7,509.9,3.407,9.91E+04
4.506,30,189.1,25,110.1,508,4.614,9.96E+04
4.506,30,193.1,25,70.44,486.9,6.913,9.99E+04
4.506,30,197.1,25,30.33,462.1,15.24,1.00E+05
4.506,30,1.006,25,9.642,474.9,49.25,19.56
4.506,30,5.007,25,49.09,474.1,9.66,176.9
4.506,30,9.008,25,88.69,408.6,4.607,494.8
4.506,30,13.01,25,129,643,4.986,972.7
4.506,30,17.01,25,168.6,652.5,3.869,1613
4.506,30,21.03,25,208.7,647.3,3.102,2419
4.506,30,25.01,25,248.3,635.9,2.561,3369
4.506,30,29.03,25,287.7,651.3,2.263,4487
4.506,30,33.03,25,328.2,749.4,2.283,5777
4.506,30,37.01,25,367.6,614.8,1.673,7199
4.506,30,41.03,25,407.4,500.2,1.228,8801
4.506,30,45.03,25,447.5,460.1,1.028,1.06E+04
4.506,30,49.01,25,487,377.4,0.7749,1.25E+04
4.506,30,53.03,25,526.7,364.8,0.6926,1.46E+04
4.506,30,57.03,25,566.8,358,0.6316,1.68E+04
4.506,30,61.01,25,606.6,401.7,0.6621,1.92E+04
4.506,30,65.03,25,646.6,367.2,0.5679,2.18E+04
4.506,30,69.03,25,686.9,353.2,0.5143,2.45E+04
4.506,30,73.01,25,725.9,356.7,0.4913,2.74E+04
4.506,30,77.03,25,766.1,351.9,0.4593,3.04E+04
4.506,30,81.03,25,806.2,330.4,0.4099,3.36E+04
4.506,30,85.01,25,845.3,293.5,0.3473,3.69E+04
4.506,30,89.03,25,885.6,296.5,0.3348,4.05E+04
4.506,30,93.03,25,925.6,289.4,0.3126,4.42E+04
4.506,30,97.01,25,964.8,294.3,0.305,4.80E+04
4.506,30,101.1,25,986.2,282.9,0.2869,5.20E+04
4.506,30,105.1,25,946.5,282.9,0.2989,5.59E+04
4.506,30,109.1,25,906.9,320.7,0.3536,5.95E+04
4.506,30,113.1,25,866.8,352.6,0.4068,6.31E+04
4.506,30,117.1,25,827,347.8,0.4205,6.64E+04
4.506,30,121.1,25,787.5,344.5,0.4375,6.96E+04
4.506,30,125.1,25,747.2,339.3,0.4541,7.27E+04
4.506,30,129.1,25,707.6,340.2,0.4808,7.56E+04
4.506,30,133.1,25,667.4,302,0.4525,7.83E+04
4.506,30,137.1,25,627.9,308,0.4905,8.08E+04
4.506,30,141.1,25,588.3,308.1,0.5237,8.32E+04
4.506,30,145.1,25,548.1,326.3,0.5954,8.55E+04
4.506,30,149.1,25,508.5,334.5,0.6579,8.76E+04
4.506,30,153.1,25,468.8,328.9,0.7015,8.95E+04
4.506,30,157.1,25,428.7,337.2,0.7865,9.13E+04
4.506,30,161.1,25,389,376.3,0.9673,9.29E+04
4.506,30,165.1,25,349,430.2,1.233,9.43E+04
4.506,30,169.1,25,309.1,433.3,1.402,9.56E+04
4.506,30,173.1,25,269.6,485,1.799,9.67E+04
4.506,30,177.1,25,229.6,445.7,1.941,9.77E+04
4.506,30,181.1,25,189.7,465.2,2.452,9.85E+04
4.506,30,185.1,25,150.1,424.6,2.828,9.91E+04
4.506,30,189.1,25,110.1,487.8,4.431,9.96E+04
4.506,30,193.1,25,70.43,524.1,7.442,9.99E+04
4.506,30,197.1,25,30.26,331.1,10.94,1.00E+05
1.74,10,1.015,25,9.894,1446,146.2,19.78
1.74,10,5.008,25,48.98,1457,29.75,176.9
1.74,10,9.019,25,88.61,1227,13.85,494.9
1.74,10,13.02,25,128.6,934.5,7.266,977.1
1.74,10,17.01,25,168.6,815.2,4.834,1613
1.74,10,21.02,25,208.6,682.7,3.273,2411
1.74,10,25.02,25,248.3,554.9,2.235,3374
1.74,10,29.01,25,287.9,451.8,1.569,4488
1.74,10,33.02,25,328,381.2,1.162,5765
1.74,10,37.02,25,367.6,324.3,0.8821,7209
1.74,10,41.01,25,407.3,282.6,0.6938,8801
1.74,10,45.02,25,447.5,230.1,0.5143,1.06E+04
1.74,10,49.02,25,487.1,199.6,0.4098,1.25E+04
1.74,10,53.01,25,526.7,181.6,0.3447,1.46E+04
1.74,10,57.02,25,566.9,176.3,0.311,1.68E+04
1.74,10,61.02,25,607,174.5,0.2874,1.92E+04
1.74,10,65.01,25,646.6,172,0.266,2.18E+04
1.74,10,69.02,25,686.2,169.4,0.2469,2.45E+04
1.74,10,73.02,25,726.4,166.9,0.2298,2.74E+04
1.74,10,77.01,25,766,164.4,0.2147,3.04E+04
1.74,10,81.02,25,805.6,161.9,0.201,3.36E+04
1.74,10,85.02,25,845.7,138.4,0.1636,3.70E+04
1.74,10,89.01,25,885.5,155.4,0.1755,4.05E+04
1.74,10,93.02,25,925.1,154.4,0.1669,4.41E+04
1.74,10,97.02,25,965.3,152.2,0.1577,4.80E+04
1.74,10,101,25,986.1,148.5,0.1506,5.20E+04
1.74,10,105.1,25,946.4,143.8,0.152,5.58E+04
1.74,10,109.1,25,906.8,141,0.1555,5.95E+04
1.74,10,113.1,25,866.7,138.4,0.1596,6.30E+04
1.74,10,117.1,25,827.1,136.2,0.1646,6.64E+04
1.74,10,121.1,25,787.3,134.6,0.171,6.96E+04
1.74,10,125.1,25,747.2,131.5,0.176,7.26E+04
1.74,10,129.1,25,707.5,129.9,0.1836,7.55E+04
1.74,10,133.1,25,667.4,126.3,0.1892,7.82E+04
1.74,10,137.1,25,627.8,124.5,0.1983,8.08E+04
1.74,10,141.1,25,588.1,121.4,0.2063,8.32E+04
1.74,10,145.1,25,548,119,0.2171,8.55E+04
1.74,10,149.1,25,508.4,117.2,0.2306,8.75E+04
1.74,10,153.1,25,468.8,114.4,0.2441,8.95E+04
1.74,10,157.1,25,428.6,111.7,0.2606,9.12E+04
1.74,10,161.1,25,389,109.9,0.2826,9.28E+04
1.74,10,165.1,25,349.3,106.6,0.305,9.43E+04
1.74,10,169.1,25,309.2,100.8,0.3261,9.55E+04
1.74,10,173.1,25,269.6,96.4,0.3576,9.67E+04
1.74,10,177.1,25,229.9,89.04,0.3873,9.76E+04
1.74,10,181.1,25,189.8,79.96,0.4213,9.84E+04
1.74,10,185.1,25,150.1,69.83,0.4651,9.91E+04
1.74,10,189.1,25,110.5,57.56,0.5209,9.96E+04
1.74,10,193.1,25,70.38,44.47,0.6319,9.99E+04
1.74,10,197.1,25,30.74,32.98,1.073,1.00E+05
1.74,10,1.004,25,9.616,506.8,52.71,19.04
1.74,10,5.008,25,49.08,552.6,11.26,178
1.74,10,9.007,25,88.72,556.9,6.277,494.9
1.74,10,13.01,25,128.9,670.1,5.199,974.9
1.74,10,17.01,25,168.5,543.7,3.227,1613
1.74,10,21.01,25,208.6,501,2.401,2411
1.74,10,25.01,25,248.3,441.9,1.78,3370
1.74,10,29.01,25,287.9,379,1.316,4488
1.74,10,33.01,25,328,338.4,1.031,5765
1.74,10,37.01,25,367.7,318.5,0.8663,7203
1.74,10,41.01,25,407.3,298.5,0.7328,8801
1.74,10,45.03,25,447.5,273.2,0.6105,1.06E+04
1.74,10,49.01,25,487.1,258.3,0.5303,1.25E+04
1.74,10,53.03,25,526.8,244.5,0.4641,1.46E+04
1.74,10,57.01,25,566.9,235.4,0.4153,1.68E+04
1.74,10,61.01,25,606.5,228.8,0.3772,1.92E+04
1.74,10,65.03,25,646.6,219.4,0.3394,2.18E+04
1.74,10,69.03,25,686.7,214.6,0.3124,2.45E+04
1.74,10,73.01,25,725.9,212.6,0.2928,2.74E+04
1.74,10,77.03,25,766.1,213.7,0.2789,3.04E+04
1.74,10,81.03,25,806.2,215.9,0.2678,3.36E+04
1.74,10,85.01,25,845.3,212,0.2508,3.69E+04
1.74,10,89.03,25,885.5,210.2,0.2374,4.05E+04
1.74,10,93.03,25,925.6,206.6,0.2232,4.42E+04
1.74,10,97.01,25,964.8,202.7,0.2101,4.80E+04
1.74,10,101.1,25,986.1,198.6,0.2014,5.20E+04
1.74,10,105.1,25,946.5,196.5,0.2077,5.59E+04
1.74,10,109.1,25,906.8,191.4,0.211,5.95E+04
1.74,10,113.1,25,866.7,188.2,0.2171,6.31E+04
1.74,10,117.1,25,827.1,184.7,0.2234,6.64E+04
1.74,10,121.1,25,787.5,181.8,0.2309,6.96E+04
1.74,10,125.1,25,747.2,178.6,0.239,7.27E+04
1.74,10,129.1,25,707.6,175.6,0.2481,7.56E+04
1.74,10,133.1,25,667.5,173,0.2592,7.83E+04
1.74,10,137.1,25,627.9,170.6,0.2716,8.09E+04
1.74,10,141.1,25,587.8,167.7,0.2853,8.33E+04
1.74,10,145.1,25,548.1,165.3,0.3016,8.55E+04
1.74,10,149.1,25,508.5,161.9,0.3183,8.76E+04
1.74,10,153.1,25,468.3,159.4,0.3404,8.95E+04
1.74,10,157.1,25,428.7,156.7,0.3654,9.13E+04
1.74,10,161.1,25,389,153.5,0.3947,9.29E+04
1.74,10,165.1,25,348.9,149.2,0.4276,9.43E+04
1.74,10,169.1,25,309.2,143.7,0.4647,9.56E+04
1.74,10,173.1,25,269.6,137.8,0.5112,9.67E+04
1.74,10,177.1,25,229.5,125.9,0.5484,9.77E+04
1.74,10,181.1,25,189.9,113.7,0.5991,9.85E+04
1.74,10,185.1,25,150.2,100.1,0.6664,9.91E+04
1.74,10,189.1,25,110.1,79.72,0.7242,9.96E+04
1.74,10,193.1,25,70.44,77.91,1.106,9.99E+04
1.74,10,197.1,25,30.31,54.02,1.782,1.00E+05
1.74,10,1.004,25,9.517,197.8,20.79,19.05
1.74,10,5.009,25,49.07,178.2,3.631,178
1.74,10,9.007,25,88.71,187.9,2.118,494.9
1.74,10,13.01,25,128.8,159.8,1.24,974.9
1.74,10,17.01,25,168.5,151.1,0.8967,1613
1.74,10,21.01,25,208.6,151.5,0.7263,2411
1.74,10,25.01,25,248.3,151.7,0.611,3370
1.74,10,29.01,25,287.9,152.7,0.5303,4488
1.74,10,33.01,25,328,148.4,0.4525,5765
1.74,10,37.01,25,367.6,141.3,0.3844,7203
1.74,10,41.01,25,407.3,133.7,0.3283,8801
1.74,10,45.01,25,447.4,130,0.2906,1.06E+04
1.74,10,49.03,25,487.1,122.3,0.2511,1.25E+04
1.74,10,53.01,25,526.7,119.6,0.227,1.46E+04
1.74,10,57.01,25,566.9,116.1,0.2047,1.68E+04
1.74,10,61.03,25,606.5,114.8,0.1893,1.92E+04
1.74,10,65.03,25,646.6,111.7,0.1728,2.18E+04
1.74,10,69.01,25,686.3,110.4,0.1609,2.45E+04
1.74,10,73.03,25,725.9,109.5,0.1508,2.74E+04
1.74,10,77.03,25,766.1,108,0.141,3.04E+04
1.74,10,81.01,25,805.6,107.1,0.1329,3.36E+04
1.74,10,85.03,25,845.3,103.1,0.122,3.69E+04
1.74,10,89.03,25,885.5,105.9,0.1196,4.05E+04
1.74,10,93.01,25,925.1,105.6,0.1141,4.41E+04
1.74,10,97.03,25,964.8,104.9,0.1088,4.80E+04
1.74,10,101,25,986.1,102.3,0.1037,5.20E+04
1.74,10,105.1,25,946.5,99.19,0.1048,5.58E+04
1.74,10,109.1,25,906.8,97.11,0.1071,5.95E+04
1.74,10,113.1,25,866.6,95.65,0.1104,6.30E+04
1.74,10,117.1,25,827,93.86,0.1135,6.64E+04
1.74,10,121.1,25,787.4,91.39,0.1161,6.96E+04
1.74,10,125.1,25,747.2,90.83,0.1216,7.26E+04
1.74,10,129.1,25,707.6,89.6,0.1266,7.55E+04
1.74,10,133.1,25,667.5,87.99,0.1318,7.82E+04
1.74,10,137.1,25,627.9,86.65,0.138,8.08E+04
1.74,10,141.1,25,588.2,84.61,0.1438,8.32E+04
1.74,10,145.1,25,548.1,83.57,0.1525,8.55E+04
1.74,10,149.1,25,508.4,81.68,0.1607,8.75E+04
1.74,10,153.1,25,468.8,79.52,0.1696,8.95E+04
1.74,10,157.1,25,428.7,79.25,0.1849,9.12E+04
1.74,10,161.1,25,389,77.09,0.1982,9.28E+04
1.74,10,165.1,25,348.9,75.43,0.2162,9.43E+04
1.74,10,169.1,25,309.2,72.1,0.2332,9.55E+04
1.74,10,173.1,25,269.6,67.1,0.2489,9.67E+04
1.74,10,177.1,25,229.5,65.14,0.2839,9.76E+04
1.74,10,181.1,25,189.9,61.76,0.3253,9.84E+04
1.74,10,185.1,25,150.2,56.31,0.3749,9.91E+04
1.74,10,189.1,25,110.1,48.19,0.4378,9.96E+04
1.74,10,193.1,25,70.42,35.25,0.5005,9.99E+04
1.74,10,197.1,25,30.29,24.05,0.7941,1.00E+05
1.74,20,1.004,25,9.554,189.7,19.85,19.04
1.74,20,5.013,25,49.07,90.94,1.853,178
1.74,20,9.012,25,89.21,103.5,1.161,496.5
1.74,20,13.01,25,128.9,74.08,0.5749,974.9
1.74,20,17.01,25,168.5,61.64,0.3659,1610
1.74,20,21.01,25,208.6,56.96,0.273,2411
1.74,20,25.01,25,248.3,50.91,0.2051,3370
1.74,20,29.01,25,287.9,40.08,0.1392,4488
1.74,20,33.01,25,328,39.98,0.1219,5765
1.74,20,37.01,25,367.7,38.75,0.1054,7203
1.74,20,41.01,25,407.3,39.4,0.09673,8801
1.74,20,45.01,25,447.5,36.99,0.08268,1.06E+04
1.74,20,49.01,25,487.1,36.4,0.07473,1.25E+04
1.74,20,53.01,25,526.8,35.36,0.06712,1.46E+04
1.74,20,57.01,25,566.9,36.36,0.06414,1.68E+04
1.74,20,61.01,25,606.5,35.92,0.05922,1.92E+04
1.74,20,65.01,25,646.6,36.51,0.05646,2.18E+04
1.74,20,69.01,25,686.3,36.32,0.05293,2.45E+04
1.74,20,73.01,25,725.9,36.61,0.05044,2.74E+04
1.74,20,77.01,25,766.1,36.16,0.04719,3.04E+04
1.74,20,81.01,25,805.7,36.41,0.04519,3.36E+04
1.74,20,85.01,25,845.3,36.19,0.04281,3.69E+04
1.74,20,89.01,25,885.5,36.58,0.04131,4.05E+04
1.74,20,93.01,25,925.1,36.26,0.03919,4.41E+04
1.74,20,97.01,25,964.8,36.2,0.03752,4.80E+04
1.74,20,101.1,25,985.7,34.63,0.03513,5.20E+04
1.74,20,105.1,25,946.5,33.77,0.03568,5.58E+04
1.74,20,109.1,25,906.4,33.86,0.03736,5.95E+04
1.74,20,113.1,25,866.3,33.17,0.03828,6.31E+04
1.74,20,117.1,25,827,32.4,0.03917,6.64E+04
1.74,20,121.1,25,786.9,32.61,0.04144,6.96E+04
1.74,20,125.1,25,746.8,32.19,0.04311,7.27E+04
1.74,20,129.1,25,707.2,32.17,0.04549,7.55E+04
1.74,20,133.1,25,667.5,31.8,0.04764,7.83E+04
1.74,20,137.1,25,627.3,31.43,0.0501,8.08E+04
1.74,20,141.1,25,587.7,30.77,0.05236,8.32E+04
1.74,20,145.1,25,548.1,30.15,0.05501,8.55E+04
1.74,20,149.1,25,508,29.29,0.05767,8.75E+04
1.74,20,153.1,25,468.3,27.98,0.05975,8.95E+04
1.74,20,157.1,25,428.7,28.54,0.06657,9.12E+04
1.74,20,161.1,25,388.6,23.9,0.06149,9.28E+04
1.74,20,165.1,25,348.9,26.22,0.07514,9.43E+04
1.74,20,169.1,25,309.3,22.76,0.07359,9.55E+04
1.74,20,173.1,25,269.2,16.28,0.06047,9.67E+04
1.74,20,177.1,25,229.5,16.61,0.07237,9.76E+04
1.74,20,181.1,25,189.9,15.23,0.08023,9.84E+04
1.74,20,185.1,25,149.7,14.99,0.1001,9.91E+04
1.74,20,189.1,25,110.1,13.86,0.1259,9.96E+04
1.74,20,193.1,25,70.46,11.38,0.1615,9.99E+04
1.74,20,197.1,25,30.32,9.206,0.3036,1.00E+05
1.74,20,1.004,25,9.527,165.4,17.36,19.07
1.74,20,5.008,25,49.06,89.82,1.831,177
1.74,20,9.007,25,88.73,91.55,1.032,494.9
1.74,20,13.01,25,128.9,66.58,0.5167,975
1.74,20,17.01,25,168.5,58.72,0.3485,1613
1.74,20,21.01,25,208.6,52.48,0.2516,2411
1.74,20,25.01,25,248.3,43.86,0.1767,3370
1.74,20,29.01,25,287.9,37.36,0.1298,4488
1.74,20,33.01,25,328,37.46,0.1142,5765
1.74,20,37.01,25,367.6,33.92,0.09227,7203
1.74,20,41.01,25,407.3,33.06,0.08118,8801
1.74,20,45.01,25,447.5,31.02,0.06933,1.06E+04
1.74,20,49.01,25,487.1,30.34,0.06228,1.25E+04
1.74,20,53.01,25,526.8,29.39,0.05578,1.46E+04
1.74,20,57.01,25,566.9,30.73,0.0542,1.68E+04
1.74,20,61.01,25,606.5,29.52,0.04867,1.92E+04
1.74,20,65.01,25,646.6,30.46,0.04711,2.18E+04
1.74,20,69.01,25,686.3,31.01,0.04519,2.45E+04
1.74,20,73.01,25,725.9,30.5,0.04202,2.74E+04
1.74,20,77.01,25,766.1,31.21,0.04074,3.04E+04
1.74,20,81.01,25,805.6,30.93,0.03839,3.36E+04
1.74,20,85.01,25,845.3,29.94,0.03542,3.69E+04
1.74,20,89.01,25,885.5,30.54,0.03448,4.05E+04
1.74,20,93.01,25,925.1,30.23,0.03267,4.41E+04
1.74,20,97.01,25,964.8,30.04,0.03114,4.80E+04
1.74,20,101,25,986.1,28.41,0.02881,5.20E+04
1.74,20,105.1,25,946.5,27.35,0.02889,5.58E+04
1.74,20,109.1,25,906.8,11.63,0.01282,5.95E+04
1.74,20,113.1,25,866.7,26.9,0.03103,6.30E+04
1.74,20,117.1,25,827.1,26.55,0.0321,6.64E+04
1.74,20,121.1,25,787.4,26.79,0.03402,6.96E+04
1.74,20,125.1,25,747.2,26.15,0.035,7.27E+04
1.74,20,129.1,25,707.6,25.6,0.03618,7.55E+04
1.74,20,133.1,25,667.5,24.58,0.03682,7.82E+04
1.74,20,137.1,25,627.8,25.04,0.03989,8.08E+04
1.74,20,141.1,25,588.2,23.94,0.0407,8.32E+04
1.74,20,145.1,25,548,23.44,0.04277,8.55E+04
1.74,20,149.1,25,508.4,22.36,0.04397,8.75E+04
1.74,20,153.1,25,468.8,21.32,0.04548,8.95E+04
1.74,20,157.1,25,428.6,21.33,0.04976,9.12E+04
1.74,20,161.1,25,389,20.2,0.05194,9.28E+04
1.74,20,165.1,25,349.3,18.93,0.05419,9.43E+04
1.74,20,169.1,25,309.2,16.36,0.0529,9.55E+04
1.74,20,173.1,25,269.6,12.21,0.04528,9.67E+04
1.74,20,177.1,25,229.9,11.09,0.04821,9.76E+04
1.74,20,181.1,25,189.8,10.28,0.05418,9.84E+04
1.74,20,185.1,25,150.2,9.358,0.06232,9.91E+04
1.74,20,189.1,25,110,8.721,0.07926,9.96E+04
1.74,20,193.1,25,70.39,7.748,0.1101,9.99E+04
1.74,20,197.1,25,30.25,5.688,0.188,1.00E+05
1.74,30,1.004,25,9.443,38,4.024,19.01
1.74,30,5.007,25,49.07,43.92,0.895,177
1.74,30,9.007,25,88.71,48.24,0.5438,494.9
1.74,30,13.01,25,128.8,42.71,0.3315,974.9
1.74,30,17.01,25,168.5,41.22,0.2447,1613
1.74,30,21.01,25,208.6,41.95,0.2011,2411
1.74,30,25.01,25,248.3,41.57,0.1674,3370
1.74,30,29.01,25,287.9,41.45,0.144,4488
1.74,30,33.01,25,328,48.22,0.147,5765
1.74,30,37.01,25,367.7,46.72,0.1271,7203
1.74,30,41.01,25,407.3,46.74,0.1147,8801
1.74,30,45.01,25,447.5,47.77,0.1068,1.06E+04
1.74,30,49.01,25,487.1,48.25,0.09906,1.25E+04
1.74,30,53.01,25,526.7,49.11,0.09324,1.46E+04
1.74,30,57.01,25,566.9,49.09,0.08659,1.68E+04
1.74,30,61.01,25,606.5,51.25,0.0845,1.92E+04
1.74,30,65.01,25,646.6,51.24,0.07925,2.18E+04
1.74,30,69.01,25,686.2,51.11,0.07448,2.45E+04
1.74,30,73.01,25,725.9,51.9,0.0715,2.74E+04
1.74,30,77.01,25,766.1,52.48,0.06851,3.04E+04
1.74,30,81.01,25,805.6,52.78,0.06551,3.36E+04
1.74,30,85.01,25,845.3,53.71,0.06354,3.69E+04
1.74,30,89.01,25,885.4,54.85,0.06195,4.05E+04
1.74,30,93.01,25,925.1,55.81,0.06033,4.41E+04
1.74,30,97.01,25,964.8,56.16,0.05821,4.80E+04
1.74,30,101,25,986.1,54.87,0.05564,5.20E+04
1.74,30,105.1,25,946.5,52.53,0.0555,5.58E+04
1.74,30,109.1,25,906.8,51.59,0.05689,5.95E+04
1.74,30,113.1,25,866.7,50.11,0.05781,6.30E+04
1.74,30,117.1,25,827,49.4,0.05974,6.64E+04
1.74,30,121.1,25,787.3,48.55,0.06167,6.96E+04
1.74,30,125.1,25,747.2,47.16,0.06312,7.26E+04
1.74,30,129.1,25,707.6,46.2,0.06529,7.55E+04
1.74,30,133.1,25,667.5,45.51,0.06818,7.82E+04
1.74,30,137.1,25,627.8,45.04,0.07176,8.08E+04
1.74,30,141.1,25,588.2,43.84,0.07454,8.32E+04
1.74,30,145.1,25,548.1,42.71,0.07793,8.55E+04
1.74,30,149.1,25,508.4,41.81,0.08223,8.75E+04
1.74,30,153.1,25,468.8,41.54,0.08862,8.95E+04
1.74,30,157.1,25,428.6,40.69,0.09493,9.12E+04
1.74,30,161.1,25,389,39.75,0.1022,9.28E+04
1.74,30,165.1,25,349.3,39.51,0.1131,9.43E+04
1.74,30,169.1,25,309.2,36.08,0.1167,9.55E+04
1.74,30,173.1,25,269.6,27.29,0.1012,9.67E+04
1.74,30,177.1,25,229.9,26.8,0.1166,9.76E+04
1.74,30,181.1,25,189.8,25.39,0.1338,9.84E+04
1.74,30,185.1,25,150.2,22.92,0.1526,9.91E+04
1.74,30,189.1,25,110.5,20.24,0.1832,9.96E+04
1.74,30,193.1,25,70.37,17.14,0.2436,9.99E+04
1.74,30,197.1,25,30.24,9.415,0.3113,1.00E+05
1.74,30,1.007,25,9.501,124.4,13.09,19.36
1.74,30,5.029,25,49.56,74,1.493,180
1.74,30,9.009,25,89.21,63.68,0.7138,496.5
1.74,30,13.03,25,128.8,49.56,0.3846,974.9
1.74,30,17.03,25,169,46.2,0.2735,1619
1.74,30,21.01,25,208.6,47.31,0.2267,2411
1.74,30,25.03,25,248.3,46.47,0.1872,3370
1.74,30,29.03,25,288.4,47.63,0.1652,4497
1.74,30,33.01,25,328,54.15,0.1651,5765
1.74,30,37.03,25,367.7,53.45,0.1454,7203
1.74,30,41.03,25,407.8,52.95,0.1298,8815
1.74,30,45.01,25,447.5,54.03,0.1208,1.06E+04
1.74,30,49.03,25,487.1,55.09,0.1131,1.25E+04
1.74,30,53.03,25,527.2,57.08,0.1083,1.46E+04
1.74,30,57.01,25,566.9,57.25,0.101,1.68E+04
1.74,30,61.03,25,606.5,58.72,0.09683,1.92E+04
1.74,30,65.03,25,646.6,59.01,0.09126,2.18E+04
1.74,30,69.01,25,686.3,60.39,0.088,2.45E+04
1.74,30,73.03,25,725.9,61.44,0.08464,2.74E+04
1.74,30,77.03,25,766.1,61.73,0.08057,3.04E+04
1.74,30,81.01,25,805.7,61.72,0.07661,3.36E+04
1.74,30,85.03,25,845.3,62.62,0.07408,3.69E+04
1.74,30,89.03,25,885.5,63.55,0.07176,4.05E+04
1.74,30,93.01,25,925.1,63.81,0.06897,4.41E+04
1.74,30,97.03,25,964.8,64.95,0.06732,4.80E+04
1.74,30,101,25,986.2,63.46,0.06435,5.20E+04
1.74,30,105.1,25,946.5,60.46,0.06388,5.58E+04
1.74,30,109.1,25,906.8,59.38,0.06548,5.95E+04
1.74,30,113.1,25,866.7,57.68,0.06655,6.30E+04
1.74,30,117.1,25,827.1,56.53,0.06835,6.64E+04
1.74,30,121.1,25,787.4,55.25,0.07017,6.96E+04
1.74,30,125.1,25,747.2,54.13,0.07245,7.26E+04
1.74,30,129.1,25,707.6,53.31,0.07534,7.55E+04
1.74,30,133.1,25,667.4,51.92,0.07779,7.82E+04
1.74,30,137.1,25,627.8,50.81,0.08094,8.08E+04
1.74,30,141.1,25,588.2,49.68,0.08445,8.32E+04
1.74,30,145.1,25,548.1,48.49,0.08847,8.55E+04
1.74,30,149.1,25,508.5,47.85,0.09411,8.75E+04
1.74,30,153.1,25,468.3,45.92,0.09806,8.95E+04
1.74,30,157.1,25,428.7,45.68,0.1066,9.12E+04
1.74,30,161.1,25,389,44.53,0.1145,9.28E+04
1.74,30,165.1,25,348.9,43.65,0.1251,9.43E+04
1.74,30,169.1,25,309.3,40.35,0.1305,9.55E+04
1.74,30,173.1,25,269.6,32.88,0.122,9.67E+04
1.74,30,177.1,25,229.5,31.6,0.1377,9.76E+04
1.74,30,181.1,25,189.9,29.18,0.1537,9.84E+04
1.74,30,185.1,25,150.2,27.01,0.1798,9.91E+04
1.74,30,189.1,25,110.1,22.83,0.2074,9.96E+04
1.74,30,193.1,25,70.43,15.97,0.2267,9.99E+04
1.74,30,197.1,25,30.3,11.01,0.3635,1.00E+05
1.74,30,199.1,25,10.48,5.667,0.541,1.00E+05